Workbook
Name RAPORSUMATIF: #REF!
Name NamaKelasSaatKelasX: MASTER!$F$4:$F$60
Name NAMAP5: 'OLAH P5'!$D$6:$D$55
Name RAPORSUMATIF: Cetak!$A$1:$R$53
Name HEADERGABCK: 'GAB-CK'!$A$2:$AZ$2
Name HeaderInputSumatif: 'INPUT SUMATIF'!$A$2:$CH$2
Name DataBiodataSetting: SETTING!$E$3:$AH$56
Name DataNamaInputCP: 'INPUT CP'!$D$4:$D$53
Name HeaderInputCP: 'INPUT CP'!$3:$3
Name NamaKelasSaatXI: MASTER!$F$4:$F$60
Name RAPORCK2: Cetak!$S$103:$AB$151
Name DataPembentukUS: 'PEMBENTUK US'!$A$5:$CH$54
Name DataInputSumatif: 'INPUT SUMATIF'!$A$5:$CH$54
Name NIPWalas: MASTER!$AT$4:$AT$60
Name HeaderPembentukUS: 'PEMBENTUK US'!$A$2:$CH$2
Name HeaderBiodata: SETTING!$E$2:$AH$2
Name masterKonsKeahlian: MASTER!$AM$4:$AM$30
Name RAPORCK1: Cetak!$S$58:$AB$82
Name KelasWalas: MASTER!$AR$4:$AR$30
Name DataNamaInputSumatif: 'INPUT SUMATIF'!$D$5:$D$54
Name masterProgKeahlian: MASTER!$AN$4:$AN$30
Name RAPORCK1: #REF!
Name NamaRombelXI: MASTER!$AN$4:$AN$60
Name NamaKelasSaatXII: MASTER!$AJ$4:$AJ$60
Name DATAP5: 'OLAH P5'!$A$6:$AB$55
Name NamaWalas: MASTER!$AS$4:$AS$60
Name HEADERGABSUM: 'GAB-SUM'!$A$1:$CD$1
Name NamaBiodata: SETTING!$H$3:$H$56
Name NamaRombelXII: MASTER!$AO$4:$AO$60
Name DataNamaPembentukUS: 'PEMBENTUK US'!$D$5:$D$54
Name HEADERP5: 'OLAH P5'!$2:$2
Name TahunPelajaran: MASTER!$AQ$4:$AQ$30
Name masternamsiswa: MASTER!$B$4:$F$60
Name masterkkelasnya: MASTER!$F$4:$F$60
Name RAPORCK2: #REF!
Name DataInputCP: 'INPUT CP'!$A$4:$BB$53

Sheet INPUT SUMATIF
A1: 1 | B1: 2 | C1: 3 | D1: 4 | E1: 5 | F1: 6 | G1: 7 | H1: 8 | I1: 9 | J1: 10 | K1: 11 | L1: 12 | M1: 13 | N1: 14 | O1: 15 | P1: 16 | Q1: 17 | R1: 18 | S1: 19 | T1: 20 | U1: 21 | V1: 22 | W1: 23 | X1: 24 | Y1: 25 | Z1: 26 | AA1: 27 | AB1: 28 | AC1: 29 | AD1: 30 | AE1: 31 | AF1: 32 | AG1: 33 | AH1: 34 | AI1: 35 | AJ1: 36 | AK1: 37 | AL1: 37 | AM1: 39 | AN1: 40 | AO1: 41 | AP1: 42 | AQ1: 43 | AR1: 44 | AS1: 45 | AT1: 46 | AU1: 47 | AV1: 48 | AW1: 49 | AX1: 50 | AY1: 51 | AZ1: 52 | BA1: 53 | BB1: 54 | BC1: 55 | BD1: 56 | BE1: 57 | BF1: 58 | BG1: 59 | BH1: 60 | BI1: 61 | BJ1: 62 | BK1: 63 | BL1: 64 | BM1: 65 | BN1: 66 | BO1: 67 | BP1: 68 | BQ1: 69 | BR1: 70 | BS1: 71 | BT1: 76 | BU1: 72 | BV1: 73 | BW1: 74 | BX1: 75 | BY1: 76 | BZ1: 77 | CA1: 78 | CB1: 79 | CC1: 80 | CD1: 81 | CE1: 82 | CF1: 83 | CG1: 84 | CH1: 85
A2: =A3 -> NO | B2: =B3 -> NIS | C2: =C3 -> NISN | D2: =D3 -> NAMA | E2: =E3 -> KELAS | F2: =F3 -> SEMESTER | G2: =$H3&" "&G4 -> PAI SUMATIF 1 | H2: =$H3&" "&H4 -> PAI SUMATIF 2 | I2: =$H3&" "&I4 -> PAI SUMATIF 3 | J2: =$H3&" "&J4 -> PAI RATA-RATA SUMATIF | K2: =$H3&" "&K4 -> PAI NILAI SUMATIF AKHIR | L2: =$M3&" "&L4 -> PKN SUMATIF 1 | M2: =$M3&" "&M4 -> PKN SUMATIF 2 | N2: =$M3&" "&N4 -> PKN SUMATIF 3 | O2: =$M3&" "&O4 -> PKN RATA-RATA SUMATIF | P2: =$M3&" "&P4 -> PKN NILAI SUMATIF AKHIR | Q2: =$R3&" "&Q4 -> B. INDONESIA SUMATIF 1 | R2: =$R3&" "&R4 -> B. INDONESIA SUMATIF 2 | S2: =$R3&" "&S4 -> B. INDONESIA SUMATIF 3 | T2: =$R3&" "&T4 -> B. INDONESIA RATA-RATA SUMATIF | U2: =$R3&" "&U4 -> B. INDONESIA NILAI SUMATIF AKHIR | V2: =$W3&" "&V4 -> PJOK SUMATIF 1 | W2: =$W3&" "&W4 -> PJOK SUMATIF 2 | X2: =$W3&" "&X4 -> PJOK SUMATIF 3 | Y2: =$W3&" "&Y4 -> PJOK RATA-RATA SUMATIF | Z2: =$W3&" "&Z4 -> PJOK NILAI SUMATIF AKHIR | AA2: =$AB3&" "&AA4 -> SEJARAH SUMATIF 1 | AB2: =$AB3&" "&AB4 -> SEJARAH SUMATIF 2 | AC2: =$AB3&" "&AC4 -> SEJARAH SUMATIF 3 | AD2: =$AB3&" "&AD4 -> SEJARAH RATA-RATA SUMATIF | AE2: =$AB3&" "&AE4 -> SEJARAH NILAI SUMATIF AKHIR | AF2: =$AG3&" "&AF4 -> SENI BUDAYA SUMATIF 1 | AG2: =$AG3&" "&AG4 -> SENI BUDAYA SUMATIF 2 | AH2: =$AG3&" "&AH4 -> SENI BUDAYA SUMATIF 3 | AI2: =$AG3&" "&AI4 -> SENI BUDAYA RATA-RATA SUMATIF | AJ2: =$AG3&" "&AJ4 -> SENI BUDAYA NILAI SUMATIF AKHIR | AK2: =$AL3&" "&AK4 -> B. SUNDA SUMATIF 1 | AL2: =$AL3&" "&AL4 -> B. SUNDA SUMATIF 2 | AM2: =$AL3&" "&AM4 -> B. SUNDA SUMATIF 3 | AN2: =$AL3&" "&AN4 -> B. SUNDA RATA-RATA SUMATIF | AO2: =$AL3&" "&AO4 -> B. SUNDA NILAI SUMATIF AKHIR | AP2: =$AQ3&" "&AP4 -> MATEMATIKA SUMATIF 1 | AQ2: =$AQ3&" "&AQ4 -> MATEMATIKA SUMATIF 2 | AR2: =$AQ3&" "&AR4 -> MATEMATIKA SUMATIF 3 | AS2: =$AQ3&" "&AS4 -> MATEMATIKA RATA-RATA SUMATIF | AT2: =$AQ3&" "&AT4 -> MATEMATIKA NILAI SUMATIF AKHIR | AU2: =$AV3&" "&AU4 -> B. INGGRIS SUMATIF 1 | AV2: =$AV3&" "&AV4 -> B. INGGRIS SUMATIF 2 | AW2: =$AV3&" "&AW4 -> B. INGGRIS SUMATIF 3 | AX2: =$AV3&" "&AX4 -> B. INGGRIS RATA-RATA SUMATIF | AY2: =$AV3&" "&AY4 -> B. INGGRIS NILAI SUMATIF AKHIR | AZ2: =$BA3&" "&AZ4 -> INFORMATIKA SUMATIF 1 | BA2: =$BA3&" "&BA4 -> INFORMATIKA SUMATIF 2 | BB2: =$BA3&" "&BB4 -> INFORMATIKA SUMATIF 3 | BC2: =$BA3&" "&BC4 -> INFORMATIKA RATA-RATA SUMATIF | BD2: =$BA3&" "&BD4 -> INFORMATIKA NILAI SUMATIF AKHIR | BE2: =$BF3&" "&BE4 -> PROJEK IPAS SUMATIF 1 | BF2: =$BF3&" "&BF4 -> PROJEK IPAS SUMATIF 2 | BG2: =$BF3&" "&BG4 -> PROJEK IPAS SUMATIF 3 | BH2: =$BF3&" "&BH4 -> PROJEK IPAS RATA-RATA SUMATIF | BI2: =$BF3&" "&BI4 -> PROJEK IPAS NILAI SUMATIF AKHIR | BJ2: =$BK3&" "&BJ4 -> DDPK SUMATIF 1 | BK2: =$BK3&" "&BK4 -> DDPK SUMATIF 2 | BL2: =$BK3&" "&BL4 -> DDPK SUMATIF 3 | BM2: =$BK3&" "&BM4 -> DDPK RATA-RATA SUMATIF | BN2: =$BK3&" "&BN4 -> DDPK NILAI SUMATIF AKHIR | BO2: =$BP3&" "&BO4 -> KODING SUMATIF 1 | BP2: =$BP3&" "&BP4 -> KODING SUMATIF 2 | BQ2: =$BP3&" "&BQ4 -> KODING SUMATIF 3 | BR2: =$BP3&" "&BR4 -> KODING RATA-RATA SUMATIF | BS2: =$BP3&" "&BS4 -> KODING NILAI SUMATIF AKHIR | BT2: =$BU3&" "&BT4 -> KONS. KEAHLIAN SUMATIF 1 | BU2: =$BU3&" "&BU4 -> KONS. KEAHLIAN SUMATIF 2 | BV2: =$BU3&" "&BV4 -> KONS. KEAHLIAN SUMATIF 3 | BW2: =$BU3&" "&BW4 -> KONS. KEAHLIAN RATA-RATA SUMATIF | BX2: =$BU3&" "&BX4 -> KONS. KEAHLIAN NILAI SUMATIF AKHIR | BY2: =$BZ3&" "&BY4 -> PKK SUMATIF 1 | BZ2: =$BZ3&" "&BZ4 -> PKK SUMATIF 2 | CA2: =$BZ3&" "&CA4 -> PKK SUMATIF 3 | CB2: =$BZ3&" "&CB4 -> PKK RATA-RATA SUMATIF | CC2: =$BZ3&" "&CC4 -> PKK NILAI SUMATIF AKHIR | CD2: =$CE3&" "&CD4 -> MAPEL PILIHAN SUMATIF 1 | CE2: =$CE3&" "&CE4 -> MAPEL PILIHAN SUMATIF 2 | CF2: =$CE3&" "&CF4 -> MAPEL PILIHAN SUMATIF 3 | CG2: =$CE3&" "&CG4 -> MAPEL PILIHAN RATA-RATA SUMATIF | CH2: =$CE3&" "&CH4 -> MAPEL PILIHAN NILAI SUMATIF AKHIR
A3: NO | B3: NIS | C3: NISN | D3: NAMA | E3: KELAS | F3: SEMESTER | G3: 🕌 | H3: PAI | K3: Kolom PSAT | L3: 🏛️ | M3: PKN | P3: Kolom PSAT | Q3: 📖 | R3: B. INDONESIA | U3: Kolom PSAT | V3: ⚽ | W3: PJOK | Z3: Kolom PSAT | AA3: 📜 | AB3: SEJARAH | AE3: Kolom PSAT | AF3: 🎨 | AG3: SENI BUDAYA | AJ3: Kolom PSAT | AK3: 🏞️ | AL3: B. SUNDA | AO3: Kolom PSAT | AP3: ✖️ ➖ | AQ3: MATEMATIKA | AT3: Kolom PSAT | AU3: 📘 | AV3: B. INGGRIS | AY3: Kolom PSAT | AZ3: 💻 | BA3: INFORMATIKA | BD3: Kolom PSAT | BE3: 🔬 | BF3: PROJEK IPAS | BI3: Kolom PSAT | BJ3: 🛠️ | BK3: DDPK | BN3: Kolom PSAT | BO3: 👨🏻‍💻 | BP3: KODING | BS3: Kolom PSAT | BT3: 🚗 | BU3: KONS. KEAHLIAN | BX3: Kolom PSAT | BY3: 💰 | BZ3: PKK | CC3: Kolom PSAT | CD3: 🎯 | CE3: MAPEL PILIHAN | CH3: Kolom PSAT
G4: SUMATIF 1 | H4: SUMATIF 2 | I4: SUMATIF 3 | J4: RATA-RATA SUMATIF | K4: NILAI SUMATIF AKHIR | L4: SUMATIF 1 | M4: SUMATIF 2 | N4: SUMATIF 3 | O4: RATA-RATA SUMATIF | P4: NILAI SUMATIF AKHIR | Q4: SUMATIF 1 | R4: SUMATIF 2 | S4: SUMATIF 3 | T4: RATA-RATA SUMATIF | U4: NILAI SUMATIF AKHIR | V4: SUMATIF 1 | W4: SUMATIF 2 | X4: SUMATIF 3 | Y4: RATA-RATA SUMATIF | Z4: NILAI SUMATIF AKHIR | AA4: SUMATIF 1 | AB4: SUMATIF 2 | AC4: SUMATIF 3 | AD4: RATA-RATA SUMATIF | AE4: NILAI SUMATIF AKHIR | AF4: SUMATIF 1 | AG4: SUMATIF 2 | AH4: SUMATIF 3 | AI4: RATA-RATA SUMATIF | AJ4: NILAI SUMATIF AKHIR | AK4: SUMATIF 1 | AL4: SUMATIF 2 | AM4: SUMATIF 3 | AN4: RATA-RATA SUMATIF | AO4: NILAI SUMATIF AKHIR | AP4: SUMATIF 1 | AQ4: SUMATIF 2 | AR4: SUMATIF 3 | AS4: RATA-RATA SUMATIF | AT4: NILAI SUMATIF AKHIR | AU4: SUMATIF 1 | AV4: SUMATIF 2 | AW4: SUMATIF 3 | AX4: RATA-RATA SUMATIF | AY4: NILAI SUMATIF AKHIR | AZ4: SUMATIF 1 | BA4: SUMATIF 2 | BB4: SUMATIF 3 | BC4: RATA-RATA SUMATIF | BD4: NILAI SUMATIF AKHIR | BE4: SUMATIF 1 | BF4: SUMATIF 2 | BG4: SUMATIF 3 | BH4: RATA-RATA SUMATIF | BI4: NILAI SUMATIF AKHIR | BJ4: SUMATIF 1 | BK4: SUMATIF 2 | BL4: SUMATIF 3 | BM4: RATA-RATA SUMATIF | BN4: NILAI SUMATIF AKHIR | BO4: SUMATIF 1 | BP4: SUMATIF 2 | BQ4: SUMATIF 3 | BR4: RATA-RATA SUMATIF | BS4: NILAI SUMATIF AKHIR | BT4: SUMATIF 1 | BU4: SUMATIF 2 | BV4: SUMATIF 3 | BW4: RATA-RATA SUMATIF | BX4: NILAI SUMATIF AKHIR | BY4: SUMATIF 1 | BZ4: SUMATIF 2 | CA4: SUMATIF 3 | CB4: RATA-RATA SUMATIF | CC4: NILAI SUMATIF AKHIR | CD4: SUMATIF 1 | CE4: SUMATIF 2 | CF4: SUMATIF 3 | CG4: RATA-RATA SUMATIF | CH4: NILAI SUMATIF AKHIR
A5: =IFERROR(__xludf.DUMMYFUNCTION("QUERY(SETTING!$E$3:$I$56, ""SELECT * WHERE Col1 IS NOT NULL"") "),1.0) -> 1 | B5: =IFERROR(__xludf.DUMMYFUNCTION("""COMPUTED_VALUE"""),"2526100414") -> 2526100414 | C5: =IFERROR(__xludf.DUMMYFUNCTION("""COMPUTED_VALUE"""),"0098742051") -> 0098742051 | D5: =IFERROR(__xludf.DUMMYFUNCTION("""COMPUTED_VALUE"""),"AHMAD FAUZI") -> AHMAD FAUZI | E5: =IFERROR(__xludf.DUMMYFUNCTION("""COMPUTED_VALUE"""),"X TO 4") -> X TO 4 | F5: {=IF(D5:D54<>"",SETTING!$C$3,"")} -> Ganjil | G5: 82 | H5: 81 | J5: =IFERROR(AVERAGE(G5:I5),"") -> 81.5 | K5: 80 | L5: 85 | M5: 80 | O5: =IFERROR(AVERAGE(L5:N5),"") -> 82.5 | P5: 82 | Q5: 85 | R5: 85 | S5: 86 | T5: =IFERROR(AVERAGE(Q5:S5),"") -> 85.333333 | U5: 87 | V5: 75 | W5: 93 | Y5: =IFERROR(AVERAGE(V5:X5),"") -> 84 | Z5: 87 | AA5: 86 | AB5: 84 | AC5: 85 | AD5: =IFERROR(AVERAGE(AA5:AC5),"") -> 85 | AE5: 81 | AF5: 90 | AG5: 90 | AH5: 90 | AI5: =IFERROR(AVERAGE(AF5:AH5),"") -> 90 | AJ5: 90 | AK5: 86 | AL5: 85 | AM5: 84 | AN5: =IFERROR(AVERAGE(AK5:AM5),"") -> 85 | AO5: 88 | AP5: 80 | AQ5: =AP5 -> 80 | AR5: =AQ5 -> 80 | AS5: =IFERROR(AVERAGE(AP5:AR5),"") -> 80 | AT5: =AS5 -> 80 | AU5: 74 | AV5: 76 | AW5: 78 | AX5: =IFERROR(AVERAGE(AU5:AW5),"") -> 76 | AY5: 75 | AZ5: 80 | BA5: 80 | BC5: =IFERROR(AVERAGE(AZ5:BB5),"") -> 80 | BD5: 80 | BE5: 80 | BF5: 0 | BG5: 0 | BH5: =IFERROR(AVERAGE(BE5:BG5),"") -> 26.666667 | BI5: 80 | BJ5: 85 | BK5: 80 | BL5: 80 | BM5: =IFERROR(AVERAGE(BJ5:BL5),"") -> 81.666667 | BN5: 80 | BO5: 79 | BP5: 80 | BQ5: 79 | BR5: =IFERROR(AVERAGE(BO5:BQ5),"") -> 79.333333 | BS5: 78 | BW5: =IFERROR(AVERAGE(BT5:BV5),"") | CB5: =IFERROR(AVERAGE(BY5:CA5),"") | CG5: =IFERROR(AVERAGE(CD5:CF5),"")
A6: =IFERROR(__xludf.DUMMYFUNCTION("""COMPUTED_VALUE"""),2.0) -> 2 | B6: =IFERROR(__xludf.DUMMYFUNCTION("""COMPUTED_VALUE"""),"2526100415") -> 2526100415 | C6: =IFERROR(__xludf.DUMMYFUNCTION("""COMPUTED_VALUE"""),"0094541761") -> 0094541761 | D6: =IFERROR(__xludf.DUMMYFUNCTION("""COMPUTED_VALUE"""),"AHMAD YOPI JUMAEDI") -> AHMAD YOPI JUMAEDI | E6: =IFERROR(__xludf.DUMMYFUNCTION("""COMPUTED_VALUE"""),"X TO 4") -> X TO 4 | F6: Ganjil | G6: 78 | H6: 77 | J6: =IFERROR(AVERAGE(G6:I6),"") -> 77.5 | K6: 75 | L6: 85 | M6: 80 | O6: =IFERROR(AVERAGE(L6:N6),"") -> 82.5 | P6: 83 | Q6: 76 | R6: 76 | S6: 78 | T6: =IFERROR(AVERAGE(Q6:S6),"") -> 76.666667 | U6: 78 | V6: 90 | W6: 90 | Y6: =IFERROR(AVERAGE(V6:X6),"") -> 90 | Z6: 90 | AA6: 78 | AB6: 76 | AC6: 77 | AD6: =IFERROR(AVERAGE(AA6:AC6),"") -> 77 | AE6: 73 | AF6: 90 | AG6: 90 | AH6: 89 | AI6: =IFERROR(AVERAGE(AF6:AH6),"") -> 89.666667 | AJ6: 88 | AK6: 78 | AL6: 73 | AM6: 72 | AN6: =IFERROR(AVERAGE(AK6:AM6),"") -> 74.333333 | AO6: 70 | AP6: 72 | AQ6: =AP6 -> 72 | AR6: =AQ6 -> 72 | AS6: =IFERROR(AVERAGE(AP6:AR6),"") -> 72 | AT6: =AS6 -> 72 | AU6: 72 | AV6: 72 | AW6: 72 | AX6: =IFERROR(AVERAGE(AU6:AW6),"") -> 72 | AY6: 72 | AZ6: 80 | BA6: 80 | BC6: =IFERROR(AVERAGE(AZ6:BB6),"") -> 80 | BD6: 80 | BE6: 0 | BF6: 0 | BG6: 0 | BH6: =IFERROR(AVERAGE(BE6:BG6),"") -> 0 | BI6: 78 | BJ6: 79 | BK6: 80 | BL6: 80 | BM6: =IFERROR(AVERAGE(BJ6:BL6),"") -> 79.666667 | BN6: 80 | BO6: 78 | BP6: 77 | BQ6: 78 | BR6: =IFERROR(AVERAGE(BO6:BQ6),"") -> 77.666667 | BS6: 77 | BW6: =IFERROR(AVERAGE(BT6:BV6),"") | CB6: =IFERROR(AVERAGE(BY6:CA6),"") | CG6: =IFERROR(AVERAGE(CD6:CF6),"")
A7: =IFERROR(__xludf.DUMMYFUNCTION("""COMPUTED_VALUE"""),3.0) -> 3 | B7: =IFERROR(__xludf.DUMMYFUNCTION("""COMPUTED_VALUE"""),"2526100416") -> 2526100416 | C7: =IFERROR(__xludf.DUMMYFUNCTION("""COMPUTED_VALUE"""),"0095885037") -> 0095885037 | D7: =IFERROR(__xludf.DUMMYFUNCTION("""COMPUTED_VALUE"""),"ALGI FALGIAN") -> ALGI FALGIAN | E7: =IFERROR(__xludf.DUMMYFUNCTION("""COMPUTED_VALUE"""),"X TO 4") -> X TO 4 | F7: Ganjil | G7: 80 | H7: 80 | J7: =IFERROR(AVERAGE(G7:I7),"") -> 80 | K7: 80 | L7: 85 | M7: 80 | O7: =IFERROR(AVERAGE(L7:N7),"") -> 82.5 | P7: 76 | Q7: 80 | R7: 80 | S7: 84 | T7: =IFERROR(AVERAGE(Q7:S7),"") -> 81.333333 | U7: 85 | V7: 75 | W7: 88 | Y7: =IFERROR(AVERAGE(V7:X7),"") -> 81.5 | Z7: 85 | AA7: 78 | AB7: 76 | AC7: 77 | AD7: =IFERROR(AVERAGE(AA7:AC7),"") -> 77 | AE7: 73 | AF7: 90 | AG7: 89 | AH7: 90 | AI7: =IFERROR(AVERAGE(AF7:AH7),"") -> 89.666667 | AJ7: 89 | AK7: 78 | AL7: 74 | AM7: 71 | AN7: =IFERROR(AVERAGE(AK7:AM7),"") -> 74.333333 | AO7: 70 | AP7: 80 | AQ7: =AP7 -> 80 | AR7: =AQ7 -> 80 | AS7: =IFERROR(AVERAGE(AP7:AR7),"") -> 80 | AT7: =AS7 -> 80 | AU7: 72 | AV7: 72 | AW7: 72 | AX7: =IFERROR(AVERAGE(AU7:AW7),"") -> 72 | AY7: 72 | AZ7: 80 | BA7: 80 | BC7: =IFERROR(AVERAGE(AZ7:BB7),"") -> 80 | BD7: 80 | BE7: 0 | BF7: 0 | BG7: 0 | BH7: =IFERROR(AVERAGE(BE7:BG7),"") -> 0 | BI7: 75 | BJ7: 79 | BK7: 80 | BL7: 80 | BM7: =IFERROR(AVERAGE(BJ7:BL7),"") -> 79.666667 | BN7: 80 | BO7: 79 | BP7: 78 | BQ7: 78 | BR7: =IFERROR(AVERAGE(BO7:BQ7),"") -> 78.333333 | BS7: 78 | BW7: =IFERROR(AVERAGE(BT7:BV7),"") | CB7: =IFERROR(AVERAGE(BY7:CA7),"") | CG7: =IFERROR(AVERAGE(CD7:CF7),"")
A8: =IFERROR(__xludf.DUMMYFUNCTION("""COMPUTED_VALUE"""),4.0) -> 4 | B8: =IFERROR(__xludf.DUMMYFUNCTION("""COMPUTED_VALUE"""),"2526100417") -> 2526100417 | C8: =IFERROR(__xludf.DUMMYFUNCTION("""COMPUTED_VALUE"""),"0095141993") -> 0095141993 | D8: =IFERROR(__xludf.DUMMYFUNCTION("""COMPUTED_VALUE"""),"ALI PERMANA") -> ALI PERMANA | E8: =IFERROR(__xludf.DUMMYFUNCTION("""COMPUTED_VALUE"""),"X TO 4") -> X TO 4 | F8: Ganjil | J8: =IFERROR(AVERAGE(G8:I8),"") | O8: =IFERROR(AVERAGE(L8:N8),"") | Q8: 85 | R8: 80 | S8: 80 | T8: =IFERROR(AVERAGE(Q8:S8),"") -> 81.666667 | U8: 0 | V8: 75 | W8: 75 | Y8: =IFERROR(AVERAGE(V8:X8),"") -> 75 | Z8: 75 | AA8: 60 | AB8: 58 | AC8: 59 | AD8: =IFERROR(AVERAGE(AA8:AC8),"") -> 59 | AE8: 55 | AF8: 88 | AG8: 88 | AH8: 88 | AI8: =IFERROR(AVERAGE(AF8:AH8),"") -> 88 | AJ8: 75 | AK8: 60 | AL8: 0 | AM8: 0 | AN8: =IFERROR(AVERAGE(AK8:AM8),"") -> 20 | AO8: 0 | AP8: 72 | AQ8: =AP8 -> 72 | AR8: =AQ8 -> 72 | AS8: =IFERROR(AVERAGE(AP8:AR8),"") -> 72 | AT8: =AS8 -> 72 | AU8: 40 | AV8: 43 | AW8: 40 | AX8: =IFERROR(AVERAGE(AU8:AW8),"") -> 41 | AY8: 41 | AZ8: 80 | BA8: 80 | BC8: =IFERROR(AVERAGE(AZ8:BB8),"") -> 80 | BD8: 80 | BE8: 0 | BF8: 0 | BG8: 0 | BH8: =IFERROR(AVERAGE(BE8:BG8),"") -> 0 | BI8: 0 | BJ8: 50 | BK8: 50 | BL8: 50 | BM8: =IFERROR(AVERAGE(BJ8:BL8),"") -> 50 | BN8: 50 | BO8: 45 | BP8: 50 | BQ8: 45 | BR8: =IFERROR(AVERAGE(BO8:BQ8),"") -> 46.666667 | BS8: 0 | BW8: =IFERROR(AVERAGE(BT8:BV8),"") | CB8: =IFERROR(AVERAGE(BY8:CA8),"") | CG8: =IFERROR(AVERAGE(CD8:CF8),"")
A9: =IFERROR(__xludf.DUMMYFUNCTION("""COMPUTED_VALUE"""),5.0) -> 5 | B9: =IFERROR(__xludf.DUMMYFUNCTION("""COMPUTED_VALUE"""),"2526100418") -> 2526100418 | C9: =IFERROR(__xludf.DUMMYFUNCTION("""COMPUTED_VALUE"""),"0107198266") -> 0107198266 | D9: =IFERROR(__xludf.DUMMYFUNCTION("""COMPUTED_VALUE"""),"AZRIL EKA NUGRAHA") -> AZRIL EKA NUGRAHA | E9: =IFERROR(__xludf.DUMMYFUNCTION("""COMPUTED_VALUE"""),"X TO 4") -> X TO 4 | F9: Ganjil | G9: 80 | H9: 81 | J9: =IFERROR(AVERAGE(G9:I9),"") -> 80.5 | K9: 77 | L9: 85 | M9: 80 | O9: =IFERROR(AVERAGE(L9:N9),"") -> 82.5 | P9: 84 | Q9: 80 | R9: 85 | S9: 86 | T9: =IFERROR(AVERAGE(Q9:S9),"") -> 83.666667 | U9: 86 | V9: 90 | W9: 86 | Y9: =IFERROR(AVERAGE(V9:X9),"") -> 88 | Z9: 88 | AA9: 86 | AB9: 84 | AC9: 85 | AD9: =IFERROR(AVERAGE(AA9:AC9),"") -> 85 | AE9: 81 | AF9: 88 | AG9: 89 | AH9: 90 | AI9: =IFERROR(AVERAGE(AF9:AH9),"") -> 89 | AJ9: 90 | AK9: 86 | AL9: 86 | AM9: 82 | AN9: =IFERROR(AVERAGE(AK9:AM9),"") -> 84.666667 | AO9: 83 | AP9: 72 | AQ9: =AP9 -> 72 | AR9: =AQ9 -> 72 | AS9: =IFERROR(AVERAGE(AP9:AR9),"") -> 72 | AT9: =AS9 -> 72 | AU9: 72 | AV9: 72 | AW9: 72 | AX9: =IFERROR(AVERAGE(AU9:AW9),"") -> 72 | AY9: 72 | AZ9: 80 | BA9: 80 | BC9: =IFERROR(AVERAGE(AZ9:BB9),"") -> 80 | BD9: 80 | BE9: 80 | BF9: 0 | BG9: 0 | BH9: =IFERROR(AVERAGE(BE9:BG9),"") -> 26.666667 | BI9: 75 | BJ9: 80 | BK9: 80 | BL9: 80 | BM9: =IFERROR(AVERAGE(BJ9:BL9),"") -> 80 | BN9: 80 | BO9: 78 | BP9: 80 | BQ9: 77 | BR9: =IFERROR(AVERAGE(BO9:BQ9),"") -> 78.333333 | BS9: 78 | BW9: =IFERROR(AVERAGE(BT9:BV9),"") | CB9: =IFERROR(AVERAGE(BY9:CA9),"") | CG9: =IFERROR(AVERAGE(CD9:CF9),"")
A10: =IFERROR(__xludf.DUMMYFUNCTION("""COMPUTED_VALUE"""),6.0) -> 6 | B10: =IFERROR(__xludf.DUMMYFUNCTION("""COMPUTED_VALUE"""),"2526100419") -> 2526100419 | C10: =IFERROR(__xludf.DUMMYFUNCTION("""COMPUTED_VALUE"""),"0096198310") -> 0096198310 | D10: =IFERROR(__xludf.DUMMYFUNCTION("""COMPUTED_VALUE"""),"DIKA MUSTIKA SAPUTRA") -> DIKA MUSTIKA SAPUTRA | E10: =IFERROR(__xludf.DUMMYFUNCTION("""COMPUTED_VALUE"""),"X TO 4") -> X TO 4 | F10: Ganjil | G10: 78 | H10: 79 | J10: =IFERROR(AVERAGE(G10:I10),"") -> 78.5 | K10: 77 | L10: 85 | M10: 80 | O10: =IFERROR(AVERAGE(L10:N10),"") -> 82.5 | P10: 83 | Q10: 76 | R10: 76 | S10: 76 | T10: =IFERROR(AVERAGE(Q10:S10),"") -> 76 | U10: 78 | V10: 95 | W10: 95 | Y10: =IFERROR(AVERAGE(V10:X10),"") -> 95 | Z10: 82 | AA10: 60 | AB10: 58 | AC10: 59 | AD10: =IFERROR(AVERAGE(AA10:AC10),"") -> 59 | AE10: 55 | AF10: 89 | AG10: 90 | AH10: 89 | AI10: =IFERROR(AVERAGE(AF10:AH10),"") -> 89.333333 | AJ10: 90 | AK10: 60 | AL10: 0 | AM10: 0 | AN10: =IFERROR(AVERAGE(AK10:AM10),"") -> 20 | AO10: 40 | AP10: 72 | AQ10: =AP10 -> 72 | AR10: =AQ10 -> 72 | AS10: =IFERROR(AVERAGE(AP10:AR10),"") -> 72 | AT10: =AS10 -> 72 | AU10: 72 | AV10: 72 | AW10: 72 | AX10: =IFERROR(AVERAGE(AU10:AW10),"") -> 72 | AY10: 72 | AZ10: 80 | BA10: 80 | BC10: =IFERROR(AVERAGE(AZ10:BB10),"") -> 80 | BD10: 80 | BE10: 0 | BF10: 0 | BG10: 0 | BH10: =IFERROR(AVERAGE(BE10:BG10),"") -> 0 | BI10: 78 | BJ10: 80 | BK10: 80 | BL10: 80 | BM10: =IFERROR(AVERAGE(BJ10:BL10),"") -> 80 | BN10: 80 | BO10: 78 | BP10: 77 | BQ10: 78 | BR10: =IFERROR(AVERAGE(BO10:BQ10),"") -> 77.666667 | BS10: 78 | BW10: =IFERROR(AVERAGE(BT10:BV10),"") | CB10: =IFERROR(AVERAGE(BY10:CA10),"") | CG10: =IFERROR(AVERAGE(CD10:CF10),"")
A11: =IFERROR(__xludf.DUMMYFUNCTION("""COMPUTED_VALUE"""),7.0) -> 7 | B11: =IFERROR(__xludf.DUMMYFUNCTION("""COMPUTED_VALUE"""),"2526100420") -> 2526100420 | C11: =IFERROR(__xludf.DUMMYFUNCTION("""COMPUTED_VALUE"""),"0092542662") -> 0092542662 | D11: =IFERROR(__xludf.DUMMYFUNCTION("""COMPUTED_VALUE"""),"FAWAZ NAUPAL ALFATIR") -> FAWAZ NAUPAL ALFATIR | E11: =IFERROR(__xludf.DUMMYFUNCTION("""COMPUTED_VALUE"""),"X TO 4") -> X TO 4 | F11: Ganjil | G11: 77 | H11: 78 | J11: =IFERROR(AVERAGE(G11:I11),"") -> 77.5 | K11: 77 | L11: 85 | M11: 80 | O11: =IFERROR(AVERAGE(L11:N11),"") -> 82.5 | P11: 80 | Q11: 80 | R11: 78 | S11: 80 | T11: =IFERROR(AVERAGE(Q11:S11),"") -> 79.333333 | U11: 80 | V11: 80 | W11: 96 | Y11: =IFERROR(AVERAGE(V11:X11),"") -> 88 | Z11: 88 | AA11: 81 | AB11: 79 | AC11: 80 | AD11: =IFERROR(AVERAGE(AA11:AC11),"") -> 80 | AE11: 76 | AF11: 88 | AG11: 90 | AH11: 90 | AI11: =IFERROR(AVERAGE(AF11:AH11),"") -> 89.333333 | AJ11: 90 | AK11: 81 | AL11: 78 | AM11: 78 | AN11: =IFERROR(AVERAGE(AK11:AM11),"") -> 79 | AO11: 75 | AP11: 75 | AQ11: =AP11 -> 75 | AR11: =AQ11 -> 75 | AS11: =IFERROR(AVERAGE(AP11:AR11),"") -> 75 | AT11: =AS11 -> 75 | AU11: 73 | AV11: 75 | AW11: 77 | AX11: =IFERROR(AVERAGE(AU11:AW11),"") -> 75 | AY11: 76 | AZ11: 80 | BA11: 80 | BC11: =IFERROR(AVERAGE(AZ11:BB11),"") -> 80 | BD11: 80 | BE11: 88 | BF11: 80 | BG11: 80 | BH11: =IFERROR(AVERAGE(BE11:BG11),"") -> 82.666667 | BI11: 80 | BJ11: 79 | BK11: 80 | BL11: 80 | BM11: =IFERROR(AVERAGE(BJ11:BL11),"") -> 79.666667 | BN11: 80 | BO11: 77 | BP11: 77 | BQ11: 78 | BR11: =IFERROR(AVERAGE(BO11:BQ11),"") -> 77.333333 | BS11: 79 | BW11: =IFERROR(AVERAGE(BT11:BV11),"") | CB11: =IFERROR(AVERAGE(BY11:CA11),"") | CG11: =IFERROR(AVERAGE(CD11:CF11),"")
A12: =IFERROR(__xludf.DUMMYFUNCTION("""COMPUTED_VALUE"""),8.0) -> 8 | B12: =IFERROR(__xludf.DUMMYFUNCTION("""COMPUTED_VALUE"""),"2526100421") -> 2526100421 | C12: =IFERROR(__xludf.DUMMYFUNCTION("""COMPUTED_VALUE"""),"0107343620") -> 0107343620 | D12: =IFERROR(__xludf.DUMMYFUNCTION("""COMPUTED_VALUE"""),"FIKRI AHMAD NAWAWI") -> FIKRI AHMAD NAWAWI | E12: =IFERROR(__xludf.DUMMYFUNCTION("""COMPUTED_VALUE"""),"X TO 4") -> X TO 4 | F12: Ganjil | G12: 80 | H12: 80 | J12: =IFERROR(AVERAGE(G12:I12),"") -> 80 | K12: 77 | L12: 85 | M12: 80 | O12: =IFERROR(AVERAGE(L12:N12),"") -> 82.5 | P12: 82 | Q12: 76 | R12: 80 | S12: 78 | T12: =IFERROR(AVERAGE(Q12:S12),"") -> 78 | U12: 78 | V12: 90 | W12: 89 | Y12: =IFERROR(AVERAGE(V12:X12),"") -> 89.5 | Z12: 84 | AA12: 81 | AB12: 79 | AC12: 80 | AD12: =IFERROR(AVERAGE(AA12:AC12),"") -> 80 | AE12: 76 | AF12: 88 | AG12: 90 | AH12: 90 | AI12: =IFERROR(AVERAGE(AF12:AH12),"") -> 89.333333 | AJ12: 89 | AK12: 81 | AL12: 79 | AM12: 80 | AN12: =IFERROR(AVERAGE(AK12:AM12),"") -> 80 | AO12: 79 | AP12: 72 | AQ12: =AP12 -> 72 | AR12: =AQ12 -> 72 | AS12: =IFERROR(AVERAGE(AP12:AR12),"") -> 72 | AT12: =AS12 -> 72 | AU12: 72 | AV12: 72 | AW12: 72 | AX12: =IFERROR(AVERAGE(AU12:AW12),"") -> 72 | AY12: 72 | AZ12: 80 | BA12: 80 | BC12: =IFERROR(AVERAGE(AZ12:BB12),"") -> 80 | BD12: 80 | BE12: 0 | BF12: 0 | BG12: 0 | BH12: =IFERROR(AVERAGE(BE12:BG12),"") -> 0 | BI12: 78 | BJ12: 82 | BK12: 80 | BL12: 80 | BM12: =IFERROR(AVERAGE(BJ12:BL12),"") -> 80.666667 | BN12: 80 | BO12: 78 | BP12: 77 | BQ12: 78 | BR12: =IFERROR(AVERAGE(BO12:BQ12),"") -> 77.666667 | BS12: 79 | BW12: =IFERROR(AVERAGE(BT12:BV12),"") | CB12: =IFERROR(AVERAGE(BY12:CA12),"") | CG12: =IFERROR(AVERAGE(CD12:CF12),"")
A13: =IFERROR(__xludf.DUMMYFUNCTION("""COMPUTED_VALUE"""),9.0) -> 9 | B13: =IFERROR(__xludf.DUMMYFUNCTION("""COMPUTED_VALUE"""),"2526100422") -> 2526100422 | C13: =IFERROR(__xludf.DUMMYFUNCTION("""COMPUTED_VALUE"""),"0076614788") -> 0076614788 | D13: =IFERROR(__xludf.DUMMYFUNCTION("""COMPUTED_VALUE"""),"HADI NURYADI") -> HADI NURYADI | E13: =IFERROR(__xludf.DUMMYFUNCTION("""COMPUTED_VALUE"""),"X TO 4") -> X TO 4 | F13: Ganjil | G13: 80 | H13: 81 | J13: =IFERROR(AVERAGE(G13:I13),"") -> 80.5 | K13: 75 | L13: 85 | M13: 80 | O13: =IFERROR(AVERAGE(L13:N13),"") -> 82.5 | P13: 85 | Q13: 78 | R13: 78 | S13: 78 | T13: =IFERROR(AVERAGE(Q13:S13),"") -> 78 | U13: 80 | V13: 75 | W13: 90 | Y13: =IFERROR(AVERAGE(V13:X13),"") -> 82.5 | Z13: 84 | AA13: 79 | AB13: 77 | AC13: 78 | AD13: =IFERROR(AVERAGE(AA13:AC13),"") -> 78 | AE13: 74 | AF13: 90 | AG13: 90 | AH13: 90 | AI13: =IFERROR(AVERAGE(AF13:AH13),"") -> 90 | AJ13: 90 | AK13: 79 | AL13: 77 | AM13: 73 | AN13: =IFERROR(AVERAGE(AK13:AM13),"") -> 76.333333 | AO13: 70 | AP13: 80 | AQ13: =AP13 -> 80 | AR13: =AQ13 -> 80 | AS13: =IFERROR(AVERAGE(AP13:AR13),"") -> 80 | AT13: =AS13 -> 80 | AU13: 72 | AV13: 72 | AW13: 72 | AX13: =IFERROR(AVERAGE(AU13:AW13),"") -> 72 | AY13: 72 | AZ13: 80 | BA13: 80 | BC13: =IFERROR(AVERAGE(AZ13:BB13),"") -> 80 | BD13: 80 | BE13: 0 | BF13: 0 | BG13: 0 | BH13: =IFERROR(AVERAGE(BE13:BG13),"") -> 0 | BI13: 80 | BJ13: 80 | BK13: 78 | BL13: 78 | BM13: =IFERROR(AVERAGE(BJ13:BL13),"") -> 78.666667 | BN13: 78 | BO13: 78 | BP13: 79 | BQ13: 77 | BR13: =IFERROR(AVERAGE(BO13:BQ13),"") -> 78 | BS13: 79 | BW13: =IFERROR(AVERAGE(BT13:BV13),"") | CB13: =IFERROR(AVERAGE(BY13:CA13),"") | CG13: =IFERROR(AVERAGE(CD13:CF13),"")
A14: =IFERROR(__xludf.DUMMYFUNCTION("""COMPUTED_VALUE"""),10.0) -> 10 | B14: =IFERROR(__xludf.DUMMYFUNCTION("""COMPUTED_VALUE"""),"2526100423") -> 2526100423 | C14: =IFERROR(__xludf.DUMMYFUNCTION("""COMPUTED_VALUE"""),"0093759169") -> 0093759169 | D14: =IFERROR(__xludf.DUMMYFUNCTION("""COMPUTED_VALUE"""),"IBNU WANALI") -> IBNU WANALI | E14: =IFERROR(__xludf.DUMMYFUNCTION("""COMPUTED_VALUE"""),"X TO 4") -> X TO 4 | F14: Ganjil | G14: 79 | H14: 80 | J14: =IFERROR(AVERAGE(G14:I14),"") -> 79.5 | K14: 77 | L14: 85 | M14: 85 | O14: =IFERROR(AVERAGE(L14:N14),"") -> 85 | P14: 79 | Q14: 80 | R14: 78 | S14: 80 | T14: =IFERROR(AVERAGE(Q14:S14),"") -> 79.333333 | U14: 80 | V14: 75 | W14: 75 | Y14: =IFERROR(AVERAGE(V14:X14),"") -> 75 | Z14: 90 | AA14: 78 | AB14: 76 | AC14: 77 | AD14: =IFERROR(AVERAGE(AA14:AC14),"") -> 77 | AE14: 73 | AF14: 90 | AG14: 89 | AH14: 90 | AI14: =IFERROR(AVERAGE(AF14:AH14),"") -> 89.666667 | AJ14: 90 | AK14: 78 | AL14: 77 | AM14: 73 | AN14: =IFERROR(AVERAGE(AK14:AM14),"") -> 76 | AO14: 70 | AP14: 76 | AQ14: =AP14 -> 76 | AR14: =AQ14 -> 76 | AS14: =IFERROR(AVERAGE(AP14:AR14),"") -> 76 | AT14: =AS14 -> 76 | AU14: 72 | AV14: 72 | AW14: 72 | AX14: =IFERROR(AVERAGE(AU14:AW14),"") -> 72 | AY14: 72 | AZ14: 80 | BA14: 80 | BC14: =IFERROR(AVERAGE(AZ14:BB14),"") -> 80 | BD14: 80 | BE14: 83 | BF14: 0 | BG14: 0 | BH14: =IFERROR(AVERAGE(BE14:BG14),"") -> 27.666667 | BI14: 83 | BJ14: 80 | BK14: 80 | BL14: 80 | BM14: =IFERROR(AVERAGE(BJ14:BL14),"") -> 80 | BN14: 80 | BO14: 79 | BP14: 78 | BQ14: 78 | BR14: =IFERROR(AVERAGE(BO14:BQ14),"") -> 78.333333 | BS14: 78 | BW14: =IFERROR(AVERAGE(BT14:BV14),"") | CB14: =IFERROR(AVERAGE(BY14:CA14),"") | CG14: =IFERROR(AVERAGE(CD14:CF14),"")
A15: =IFERROR(__xludf.DUMMYFUNCTION("""COMPUTED_VALUE"""),11.0) -> 11 | B15: =IFERROR(__xludf.DUMMYFUNCTION("""COMPUTED_VALUE"""),"2526100424") -> 2526100424 | C15: =IFERROR(__xludf.DUMMYFUNCTION("""COMPUTED_VALUE"""),"0095752965") -> 0095752965 | D15: =IFERROR(__xludf.DUMMYFUNCTION("""COMPUTED_VALUE"""),"IHSAN ABDULOH ") -> IHSAN ABDULOH | E15: =IFERROR(__xludf.DUMMYFUNCTION("""COMPUTED_VALUE"""),"X TO 4") -> X TO 4 | F15: Ganjil | G15: 80 | H15: 80 | J15: =IFERROR(AVERAGE(G15:I15),"") -> 80 | K15: 80 | L15: 85 | M15: 80 | O15: =IFERROR(AVERAGE(L15:N15),"") -> 82.5 | P15: 86 | Q15: 80 | R15: 80 | S15: 87 | T15: =IFERROR(AVERAGE(Q15:S15),"") -> 82.333333 | U15: 86 | V15: 92 | W15: 90 | Y15: =IFERROR(AVERAGE(V15:X15),"") -> 91 | Z15: 84 | AA15: 85 | AB15: 83 | AC15: 84 | AD15: =IFERROR(AVERAGE(AA15:AC15),"") -> 84 | AE15: 80 | AF15: 89 | AG15: 90 | AH15: 90 | AI15: =IFERROR(AVERAGE(AF15:AH15),"") -> 89.666667 | AJ15: 88 | AK15: 85 | AL15: 83 | AM15: 82 | AN15: =IFERROR(AVERAGE(AK15:AM15),"") -> 83.333333 | AO15: 86 | AP15: 77 | AQ15: =AP15 -> 77 | AR15: =AQ15 -> 77 | AS15: =IFERROR(AVERAGE(AP15:AR15),"") -> 77 | AT15: =AS15 -> 77 | AU15: 76 | AV15: 78 | AW15: 80 | AX15: =IFERROR(AVERAGE(AU15:AW15),"") -> 78 | AY15: 80 | AZ15: 80 | BA15: 80 | BC15: =IFERROR(AVERAGE(AZ15:BB15),"") -> 80 | BD15: 80 | BE15: 88 | BF15: 80 | BG15: 78 | BH15: =IFERROR(AVERAGE(BE15:BG15),"") -> 82 | BI15: 83 | BJ15: 84 | BK15: 85 | BL15: 85 | BM15: =IFERROR(AVERAGE(BJ15:BL15),"") -> 84.666667 | BN15: 85 | BO15: 79 | BP15: 78 | BQ15: 77 | BR15: =IFERROR(AVERAGE(BO15:BQ15),"") -> 78 | BS15: 78 | BW15: =IFERROR(AVERAGE(BT15:BV15),"") | CB15: =IFERROR(AVERAGE(BY15:CA15),"") | CG15: =IFERROR(AVERAGE(CD15:CF15),"")
A16: =IFERROR(__xludf.DUMMYFUNCTION("""COMPUTED_VALUE"""),12.0) -> 12 | B16: =IFERROR(__xludf.DUMMYFUNCTION("""COMPUTED_VALUE"""),"2526100425") -> 2526100425 | C16: =IFERROR(__xludf.DUMMYFUNCTION("""COMPUTED_VALUE"""),"0095318140") -> 0095318140 | D16: =IFERROR(__xludf.DUMMYFUNCTION("""COMPUTED_VALUE"""),"INDRA NURMAN") -> INDRA NURMAN | E16: =IFERROR(__xludf.DUMMYFUNCTION("""COMPUTED_VALUE"""),"X TO 4") -> X TO 4 | F16: Ganjil | G16: 80 | H16: 80 | J16: =IFERROR(AVERAGE(G16:I16),"") -> 80 | K16: 75 | L16: 85 | M16: 80 | O16: =IFERROR(AVERAGE(L16:N16),"") -> 82.5 | P16: 79 | Q16: 78 | R16: 80 | S16: 80 | T16: =IFERROR(AVERAGE(Q16:S16),"") -> 79.333333 | U16: 80 | V16: 75 | W16: 91 | Y16: =IFERROR(AVERAGE(V16:X16),"") -> 83 | Z16: 85 | AA16: 84 | AB16: 82 | AC16: 83 | AD16: =IFERROR(AVERAGE(AA16:AC16),"") -> 83 | AE16: 79 | AF16: 90 | AG16: 90 | AH16: 90 | AI16: =IFERROR(AVERAGE(AF16:AH16),"") -> 90 | AJ16: 89 | AK16: 84 | AL16: 85 | AM16: 82 | AN16: =IFERROR(AVERAGE(AK16:AM16),"") -> 83.666667 | AO16: 87 | AP16: 83 | AQ16: =AP16 -> 83 | AR16: =AQ16 -> 83 | AS16: =IFERROR(AVERAGE(AP16:AR16),"") -> 83 | AT16: =AS16 -> 83 | AU16: 76 | AV16: 76 | AW16: 78 | AX16: =IFERROR(AVERAGE(AU16:AW16),"") -> 76.666667 | AY16: 76 | AZ16: 80 | BA16: 80 | BC16: =IFERROR(AVERAGE(AZ16:BB16),"") -> 80 | BD16: 80 | BE16: 80 | BF16: 0 | BG16: 0 | BH16: =IFERROR(AVERAGE(BE16:BG16),"") -> 26.666667 | BI16: 82 | BJ16: 85 | BK16: 80 | BL16: 80 | BM16: =IFERROR(AVERAGE(BJ16:BL16),"") -> 81.666667 | BN16: 80 | BO16: 78 | BP16: 77 | BQ16: 78 | BR16: =IFERROR(AVERAGE(BO16:BQ16),"") -> 77.666667 | BS16: 77 | BW16: =IFERROR(AVERAGE(BT16:BV16),"") | CB16: =IFERROR(AVERAGE(BY16:CA16),"") | CG16: =IFERROR(AVERAGE(CD16:CF16),"")
A17: =IFERROR(__xludf.DUMMYFUNCTION("""COMPUTED_VALUE"""),13.0) -> 13 | B17: =IFERROR(__xludf.DUMMYFUNCTION("""COMPUTED_VALUE"""),"2526100426") -> 2526100426 | C17: =IFERROR(__xludf.DUMMYFUNCTION("""COMPUTED_VALUE"""),"3109448408") -> 3109448408 | D17: =IFERROR(__xludf.DUMMYFUNCTION("""COMPUTED_VALUE"""),"IWAN SOPYAN") -> IWAN SOPYAN | E17: =IFERROR(__xludf.DUMMYFUNCTION("""COMPUTED_VALUE"""),"X TO 4") -> X TO 4 | F17: Ganjil | G17: 80 | H17: 81 | J17: =IFERROR(AVERAGE(G17:I17),"") -> 80.5 | K17: 77 | L17: 85 | M17: 80 | O17: =IFERROR(AVERAGE(L17:N17),"") -> 82.5 | P17: 82 | Q17: 80 | R17: 85 | S17: 87 | T17: =IFERROR(AVERAGE(Q17:S17),"") -> 84 | U17: 86 | V17: 75 | W17: 86 | Y17: =IFERROR(AVERAGE(V17:X17),"") -> 80.5 | Z17: 85 | AA17: 84 | AB17: 82 | AC17: 83 | AD17: =IFERROR(AVERAGE(AA17:AC17),"") -> 83 | AE17: 79 | AF17: 90 | AG17: 88 | AH17: 90 | AI17: =IFERROR(AVERAGE(AF17:AH17),"") -> 89.333333 | AJ17: 89 | AK17: 84 | AL17: 85 | AM17: 81 | AN17: =IFERROR(AVERAGE(AK17:AM17),"") -> 83.333333 | AO17: 87 | AP17: 82 | AQ17: =AP17 -> 82 | AR17: =AQ17 -> 82 | AS17: =IFERROR(AVERAGE(AP17:AR17),"") -> 82 | AT17: =AS17 -> 82 | AU17: 76 | AV17: 78 | AW17: 80 | AX17: =IFERROR(AVERAGE(AU17:AW17),"") -> 78 | AY17: 80 | AZ17: 80 | BA17: 80 | BC17: =IFERROR(AVERAGE(AZ17:BB17),"") -> 80 | BD17: 80 | BE17: 82 | BF17: 0 | BG17: 0 | BH17: =IFERROR(AVERAGE(BE17:BG17),"") -> 27.333333 | BI17: 84 | BJ17: 85 | BK17: 80 | BL17: 80 | BM17: =IFERROR(AVERAGE(BJ17:BL17),"") -> 81.666667 | BN17: 80 | BO17: 79 | BP17: 80 | BQ17: 80 | BR17: =IFERROR(AVERAGE(BO17:BQ17),"") -> 79.666667 | BS17: 80 | BW17: =IFERROR(AVERAGE(BT17:BV17),"") | CB17: =IFERROR(AVERAGE(BY17:CA17),"") | CG17: =IFERROR(AVERAGE(CD17:CF17),"")
A18: =IFERROR(__xludf.DUMMYFUNCTION("""COMPUTED_VALUE"""),14.0) -> 14 | B18: =IFERROR(__xludf.DUMMYFUNCTION("""COMPUTED_VALUE"""),"2526100427") -> 2526100427 | C18: =IFERROR(__xludf.DUMMYFUNCTION("""COMPUTED_VALUE"""),"0097319943") -> 0097319943 | D18: =IFERROR(__xludf.DUMMYFUNCTION("""COMPUTED_VALUE"""),"JEJEN JAENI") -> JEJEN JAENI | E18: =IFERROR(__xludf.DUMMYFUNCTION("""COMPUTED_VALUE"""),"X TO 4") -> X TO 4 | F18: Ganjil | G18: 80 | H18: 81 | J18: =IFERROR(AVERAGE(G18:I18),"") -> 80.5 | K18: 80 | L18: 85 | M18: 80 | O18: =IFERROR(AVERAGE(L18:N18),"") -> 82.5 | P18: 83 | Q18: 80 | R18: 80 | S18: 86 | T18: =IFERROR(AVERAGE(Q18:S18),"") -> 82 | U18: 86 | V18: 90 | W18: 93 | Y18: =IFERROR(AVERAGE(V18:X18),"") -> 91.5 | Z18: 78 | AA18: 84 | AB18: 82 | AC18: 83 | AD18: =IFERROR(AVERAGE(AA18:AC18),"") -> 83 | AE18: 79 | AF18: 90 | AG18: 89 | AH18: 88 | AI18: =IFERROR(AVERAGE(AF18:AH18),"") -> 89 | AJ18: 88 | AK18: 84 | AL18: 84 | AM18: 81 | AN18: =IFERROR(AVERAGE(AK18:AM18),"") -> 83 | AO18: 86 | AP18: 83 | AQ18: =AP18 -> 83 | AR18: =AQ18 -> 83 | AS18: =IFERROR(AVERAGE(AP18:AR18),"") -> 83 | AT18: =AS18 -> 83 | AU18: 76 | AV18: 79 | AW18: 80 | AX18: =IFERROR(AVERAGE(AU18:AW18),"") -> 78.333333 | AY18: 80 | AZ18: 80 | BA18: 80 | BC18: =IFERROR(AVERAGE(AZ18:BB18),"") -> 80 | BD18: 80 | BE18: 83 | BF18: 80 | BG18: 82 | BH18: =IFERROR(AVERAGE(BE18:BG18),"") -> 81.666667 | BI18: 84 | BJ18: 85 | BK18: 85 | BL18: 85 | BM18: =IFERROR(AVERAGE(BJ18:BL18),"") -> 85 | BN18: 85 | BO18: 78 | BP18: 77 | BQ18: 78 | BR18: =IFERROR(AVERAGE(BO18:BQ18),"") -> 77.666667 | BS18: 78 | BW18: =IFERROR(AVERAGE(BT18:BV18),"") | CB18: =IFERROR(AVERAGE(BY18:CA18),"") | CG18: =IFERROR(AVERAGE(CD18:CF18),"")
A19: =IFERROR(__xludf.DUMMYFUNCTION("""COMPUTED_VALUE"""),15.0) -> 15 | B19: =IFERROR(__xludf.DUMMYFUNCTION("""COMPUTED_VALUE"""),"2526100428") -> 2526100428 | C19: =IFERROR(__xludf.DUMMYFUNCTION("""COMPUTED_VALUE"""),"0093753099") -> 0093753099 | D19: =IFERROR(__xludf.DUMMYFUNCTION("""COMPUTED_VALUE"""),"M.HASAN ASARI") -> M.HASAN ASARI | E19: =IFERROR(__xludf.DUMMYFUNCTION("""COMPUTED_VALUE"""),"X TO 4") -> X TO 4 | F19: Ganjil | G19: 82 | H19: 83 | J19: =IFERROR(AVERAGE(G19:I19),"") -> 82.5 | K19: 80 | L19: 85 | M19: 80 | O19: =IFERROR(AVERAGE(L19:N19),"") -> 82.5 | P19: 80 | Q19: 80 | R19: 80 | S19: 86 | T19: =IFERROR(AVERAGE(Q19:S19),"") -> 82 | U19: 86 | V19: 75 | W19: 95 | Y19: =IFERROR(AVERAGE(V19:X19),"") -> 85 | Z19: 86 | AA19: 85 | AB19: 83 | AC19: 84 | AD19: =IFERROR(AVERAGE(AA19:AC19),"") -> 84 | AE19: 80 | AF19: 90 | AG19: 90 | AH19: 89 | AI19: =IFERROR(AVERAGE(AF19:AH19),"") -> 89.666667 | AJ19: 89 | AK19: 85 | AL19: 83 | AM19: 82 | AN19: =IFERROR(AVERAGE(AK19:AM19),"") -> 83.333333 | AO19: 87 | AP19: 83 | AQ19: =AP19 -> 83 | AR19: =AQ19 -> 83 | AS19: =IFERROR(AVERAGE(AP19:AR19),"") -> 83 | AT19: =AS19 -> 83 | AU19: 77 | AV19: 76 | AW19: 78 | AX19: =IFERROR(AVERAGE(AU19:AW19),"") -> 77 | AY19: 78 | AZ19: 80 | BA19: 80 | BC19: =IFERROR(AVERAGE(AZ19:BB19),"") -> 80 | BD19: 80 | BE19: 87 | BF19: 80 | BG19: 82 | BH19: =IFERROR(AVERAGE(BE19:BG19),"") -> 83 | BI19: 82 | BJ19: 80 | BK19: 80 | BL19: 80 | BM19: =IFERROR(AVERAGE(BJ19:BL19),"") -> 80 | BN19: 80 | BO19: 79 | BP19: 77 | BQ19: 78 | BR19: =IFERROR(AVERAGE(BO19:BQ19),"") -> 78 | BS19: 78 | BW19: =IFERROR(AVERAGE(BT19:BV19),"") | CB19: =IFERROR(AVERAGE(BY19:CA19),"") | CG19: =IFERROR(AVERAGE(CD19:CF19),"")
A20: =IFERROR(__xludf.DUMMYFUNCTION("""COMPUTED_VALUE"""),16.0) -> 16 | B20: =IFERROR(__xludf.DUMMYFUNCTION("""COMPUTED_VALUE"""),"2526100429") -> 2526100429 | C20: =IFERROR(__xludf.DUMMYFUNCTION("""COMPUTED_VALUE"""),"0105910447") -> 0105910447 | D20: =IFERROR(__xludf.DUMMYFUNCTION("""COMPUTED_VALUE"""),"MUHAMAD ABIB RIZAL") -> MUHAMAD ABIB RIZAL | E20: =IFERROR(__xludf.DUMMYFUNCTION("""COMPUTED_VALUE"""),"X TO 4") -> X TO 4 | F20: Ganjil | G20: 80 | H20: 79 | J20: =IFERROR(AVERAGE(G20:I20),"") -> 79.5 | K20: 75 | L20: 85 | M20: 80 | O20: =IFERROR(AVERAGE(L20:N20),"") -> 82.5 | P20: 78 | Q20: 80 | R20: 80 | S20: 80 | T20: =IFERROR(AVERAGE(Q20:S20),"") -> 80 | U20: 85 | V20: 75 | W20: 83 | Y20: =IFERROR(AVERAGE(V20:X20),"") -> 79 | Z20: 85 | AA20: 81 | AB20: 79 | AC20: 80 | AD20: =IFERROR(AVERAGE(AA20:AC20),"") -> 80 | AE20: 76 | AF20: 90 | AG20: 89 | AH20: 90 | AI20: =IFERROR(AVERAGE(AF20:AH20),"") -> 89.666667 | AJ20: 90 | AK20: 81 | AL20: 81 | AM20: 79 | AN20: =IFERROR(AVERAGE(AK20:AM20),"") -> 80.333333 | AO20: 73 | AP20: 72 | AQ20: =AP20 -> 72 | AR20: =AQ20 -> 72 | AS20: =IFERROR(AVERAGE(AP20:AR20),"") -> 72 | AT20: =AS20 -> 72 | AU20: 74 | AV20: 72 | AW20: 74 | AX20: =IFERROR(AVERAGE(AU20:AW20),"") -> 73.333333 | AY20: 74 | AZ20: 80 | BA20: 80 | BC20: =IFERROR(AVERAGE(AZ20:BB20),"") -> 80 | BD20: 80 | BE20: 0 | BF20: 0 | BG20: 0 | BH20: =IFERROR(AVERAGE(BE20:BG20),"") -> 0 | BI20: 75 | BJ20: 79 | BK20: 80 | BL20: 80 | BM20: =IFERROR(AVERAGE(BJ20:BL20),"") -> 79.666667 | BN20: 80 | BO20: 78 | BP20: 78 | BQ20: 78 | BR20: =IFERROR(AVERAGE(BO20:BQ20),"") -> 78 | BS20: 78 | BW20: =IFERROR(AVERAGE(BT20:BV20),"") | CB20: =IFERROR(AVERAGE(BY20:CA20),"") | CG20: =IFERROR(AVERAGE(CD20:CF20),"")
A21: =IFERROR(__xludf.DUMMYFUNCTION("""COMPUTED_VALUE"""),17.0) -> 17 | B21: =IFERROR(__xludf.DUMMYFUNCTION("""COMPUTED_VALUE"""),"2526100430") -> 2526100430 | C21: =IFERROR(__xludf.DUMMYFUNCTION("""COMPUTED_VALUE"""),"0099084784") -> 0099084784 | D21: =IFERROR(__xludf.DUMMYFUNCTION("""COMPUTED_VALUE"""),"MUHAMAD AL FARIZ") -> MUHAMAD AL FARIZ | E21: =IFERROR(__xludf.DUMMYFUNCTION("""COMPUTED_VALUE"""),"X TO 4") -> X TO 4 | F21: Ganjil | G21: 80 | H21: 79 | J21: =IFERROR(AVERAGE(G21:I21),"") -> 79.5 | K21: 75 | L21: 85 | M21: 80 | O21: =IFERROR(AVERAGE(L21:N21),"") -> 82.5 | P21: 82 | Q21: 85 | R21: 87 | S21: 89 | T21: =IFERROR(AVERAGE(Q21:S21),"") -> 87 | U21: 89 | V21: 98 | W21: 98 | Y21: =IFERROR(AVERAGE(V21:X21),"") -> 98 | Z21: 87 | AA21: 86 | AB21: 84 | AC21: 85 | AD21: =IFERROR(AVERAGE(AA21:AC21),"") -> 85 | AE21: 81 | AF21: 90 | AG21: 90 | AH21: 89 | AI21: =IFERROR(AVERAGE(AF21:AH21),"") -> 89.666667 | AJ21: 90 | AK21: 86 | AL21: 85 | AM21: 84 | AN21: =IFERROR(AVERAGE(AK21:AM21),"") -> 85 | AO21: 86 | AP21: 72 | AQ21: =AP21 -> 72 | AR21: =AQ21 -> 72 | AS21: =IFERROR(AVERAGE(AP21:AR21),"") -> 72 | AT21: =AS21 -> 72 | AU21: 76 | AV21: 76 | AW21: 72 | AX21: =IFERROR(AVERAGE(AU21:AW21),"") -> 74.666667 | AY21: 78 | AZ21: 80 | BA21: 80 | BC21: =IFERROR(AVERAGE(AZ21:BB21),"") -> 80 | BD21: 80 | BE21: 80 | BF21: 0 | BG21: 0 | BH21: =IFERROR(AVERAGE(BE21:BG21),"") -> 26.666667 | BI21: 83 | BJ21: 83 | BK21: 80 | BL21: 80 | BM21: =IFERROR(AVERAGE(BJ21:BL21),"") -> 81 | BN21: 80 | BO21: 79 | BP21: 80 | BQ21: 79 | BR21: =IFERROR(AVERAGE(BO21:BQ21),"") -> 79.333333 | BS21: 79 | BW21: =IFERROR(AVERAGE(BT21:BV21),"") | CB21: =IFERROR(AVERAGE(BY21:CA21),"") | CG21: =IFERROR(AVERAGE(CD21:CF21),"")
A22: =IFERROR(__xludf.DUMMYFUNCTION("""COMPUTED_VALUE"""),18.0) -> 18 | B22: =IFERROR(__xludf.DUMMYFUNCTION("""COMPUTED_VALUE"""),"2526100431") -> 2526100431 | C22: =IFERROR(__xludf.DUMMYFUNCTION("""COMPUTED_VALUE"""),"0092469837") -> 0092469837 | D22: =IFERROR(__xludf.DUMMYFUNCTION("""COMPUTED_VALUE"""),"MUHAMAD ASRUL") -> MUHAMAD ASRUL | E22: =IFERROR(__xludf.DUMMYFUNCTION("""COMPUTED_VALUE"""),"X TO 4") -> X TO 4 | F22: Ganjil | G22: 80 | H22: 82 | J22: =IFERROR(AVERAGE(G22:I22),"") -> 81 | K22: 80 | L22: 85 | M22: 80 | O22: =IFERROR(AVERAGE(L22:N22),"") -> 82.5 | P22: 83 | Q22: 85 | R22: 87 | S22: 86 | T22: =IFERROR(AVERAGE(Q22:S22),"") -> 86 | U22: 85 | V22: 92 | W22: 98 | Y22: =IFERROR(AVERAGE(V22:X22),"") -> 95 | Z22: 80 | AA22: 87 | AB22: 85 | AC22: 86 | AD22: =IFERROR(AVERAGE(AA22:AC22),"") -> 86 | AE22: 82 | AF22: 88 | AG22: 90 | AH22: 90 | AI22: =IFERROR(AVERAGE(AF22:AH22),"") -> 89.333333 | AJ22: 90 | AK22: 87 | AL22: 86 | AM22: 86 | AN22: =IFERROR(AVERAGE(AK22:AM22),"") -> 86.333333 | AO22: 87 | AP22: 84 | AQ22: =AP22 -> 84 | AR22: =AQ22 -> 84 | AS22: =IFERROR(AVERAGE(AP22:AR22),"") -> 84 | AT22: =AS22 -> 84 | AU22: 74 | AV22: 76 | AW22: 80 | AX22: =IFERROR(AVERAGE(AU22:AW22),"") -> 76.666667 | AY22: 76 | AZ22: 80 | BA22: 80 | BC22: =IFERROR(AVERAGE(AZ22:BB22),"") -> 80 | BD22: 80 | BE22: 81 | BF22: 0 | BG22: 0 | BH22: =IFERROR(AVERAGE(BE22:BG22),"") -> 27 | BI22: 85 | BJ22: 85 | BK22: 85 | BL22: 85 | BM22: =IFERROR(AVERAGE(BJ22:BL22),"") -> 85 | BN22: 85 | BO22: 77 | BP22: 78 | BQ22: 78 | BR22: =IFERROR(AVERAGE(BO22:BQ22),"") -> 77.666667 | BS22: 78 | BW22: =IFERROR(AVERAGE(BT22:BV22),"") | CB22: =IFERROR(AVERAGE(BY22:CA22),"") | CG22: =IFERROR(AVERAGE(CD22:CF22),"")
A23: =IFERROR(__xludf.DUMMYFUNCTION("""COMPUTED_VALUE"""),19.0) -> 19 | B23: =IFERROR(__xludf.DUMMYFUNCTION("""COMPUTED_VALUE"""),"2526100432") -> 2526100432 | C23: =IFERROR(__xludf.DUMMYFUNCTION("""COMPUTED_VALUE"""),"0099940282") -> 0099940282 | D23: =IFERROR(__xludf.DUMMYFUNCTION("""COMPUTED_VALUE"""),"MUHAMAD FARHAN") -> MUHAMAD FARHAN | E23: =IFERROR(__xludf.DUMMYFUNCTION("""COMPUTED_VALUE"""),"X TO 4") -> X TO 4 | F23: Ganjil | G23: 83 | H23: 83 | J23: =IFERROR(AVERAGE(G23:I23),"") -> 83 | K23: 82 | L23: 85 | M23: 80 | O23: =IFERROR(AVERAGE(L23:N23),"") -> 82.5 | P23: 80 | Q23: 85 | R23: 87 | S23: 87 | T23: =IFERROR(AVERAGE(Q23:S23),"") -> 86.333333 | U23: 87 | V23: 75 | W23: 83 | Y23: =IFERROR(AVERAGE(V23:X23),"") -> 79 | Z23: 86 | AA23: 86 | AB23: 84 | AC23: 85 | AD23: =IFERROR(AVERAGE(AA23:AC23),"") -> 85 | AE23: 81 | AF23: 89 | AG23: 89 | AH23: 89 | AI23: =IFERROR(AVERAGE(AF23:AH23),"") -> 89 | AJ23: 90 | AK23: 86 | AL23: 85 | AM23: 85 | AN23: =IFERROR(AVERAGE(AK23:AM23),"") -> 85.333333 | AO23: 86 | AP23: 82 | AQ23: =AP23 -> 82 | AR23: =AQ23 -> 82 | AS23: =IFERROR(AVERAGE(AP23:AR23),"") -> 82 | AT23: =AS23 -> 82 | AU23: 74 | AV23: 76 | AW23: 80 | AX23: =IFERROR(AVERAGE(AU23:AW23),"") -> 76.666667 | AY23: 76 | AZ23: 80 | BA23: 80 | BC23: =IFERROR(AVERAGE(AZ23:BB23),"") -> 80 | BD23: 80 | BE23: 83 | BF23: 78 | BG23: 79 | BH23: =IFERROR(AVERAGE(BE23:BG23),"") -> 80 | BI23: 85 | BJ23: 85 | BK23: 80 | BL23: 80 | BM23: =IFERROR(AVERAGE(BJ23:BL23),"") -> 81.666667 | BN23: 80 | BO23: 78 | BP23: 78 | BQ23: 77 | BR23: =IFERROR(AVERAGE(BO23:BQ23),"") -> 77.666667 | BS23: 77 | BW23: =IFERROR(AVERAGE(BT23:BV23),"") | CB23: =IFERROR(AVERAGE(BY23:CA23),"") | CG23: =IFERROR(AVERAGE(CD23:CF23),"")
A24: =IFERROR(__xludf.DUMMYFUNCTION("""COMPUTED_VALUE"""),20.0) -> 20 | B24: =IFERROR(__xludf.DUMMYFUNCTION("""COMPUTED_VALUE"""),"2526100433") -> 2526100433 | C24: =IFERROR(__xludf.DUMMYFUNCTION("""COMPUTED_VALUE"""),"0088633294") -> 0088633294 | D24: =IFERROR(__xludf.DUMMYFUNCTION("""COMPUTED_VALUE"""),"MUHAMAD MIFTAH NASHIRUDIN") -> MUHAMAD MIFTAH NASHIRUDIN | E24: =IFERROR(__xludf.DUMMYFUNCTION("""COMPUTED_VALUE"""),"X TO 4") -> X TO 4 | F24: Ganjil | G24: 78 | H24: 79 | J24: =IFERROR(AVERAGE(G24:I24),"") -> 78.5 | K24: 77 | L24: 85 | M24: 80 | O24: =IFERROR(AVERAGE(L24:N24),"") -> 82.5 | P24: 84 | Q24: 80 | R24: 85 | S24: 85 | T24: =IFERROR(AVERAGE(Q24:S24),"") -> 83.333333 | U24: 86 | V24: 75 | W24: 82 | Y24: =IFERROR(AVERAGE(V24:X24),"") -> 78.5 | Z24: 75 | AA24: 82 | AB24: 80 | AC24: 81 | AD24: =IFERROR(AVERAGE(AA24:AC24),"") -> 81 | AE24: 77 | AF24: 88 | AG24: 90 | AH24: 90 | AI24: =IFERROR(AVERAGE(AF24:AH24),"") -> 89.333333 | AJ24: 89 | AK24: 82 | AL24: 81 | AM24: 81 | AN24: =IFERROR(AVERAGE(AK24:AM24),"") -> 81.333333 | AO24: 78 | AP24: 72 | AQ24: =AP24 -> 72 | AR24: =AQ24 -> 72 | AS24: =IFERROR(AVERAGE(AP24:AR24),"") -> 72 | AT24: =AS24 -> 72 | AU24: 74 | AV24: 76 | AW24: 80 | AX24: =IFERROR(AVERAGE(AU24:AW24),"") -> 76.666667 | AY24: 76 | AZ24: 80 | BA24: 80 | BC24: =IFERROR(AVERAGE(AZ24:BB24),"") -> 80 | BD24: 80 | BE24: 83 | BF24: 80 | BG24: 80 | BH24: =IFERROR(AVERAGE(BE24:BG24),"") -> 81 | BI24: 85 | BJ24: 82 | BK24: 80 | BL24: 80 | BM24: =IFERROR(AVERAGE(BJ24:BL24),"") -> 80.666667 | BN24: 80 | BO24: 79 | BP24: 80 | BQ24: 79 | BR24: =IFERROR(AVERAGE(BO24:BQ24),"") -> 79.333333 | BS24: 79 | BW24: =IFERROR(AVERAGE(BT24:BV24),"") | CB24: =IFERROR(AVERAGE(BY24:CA24),"") | CG24: =IFERROR(AVERAGE(CD24:CF24),"")
A25: =IFERROR(__xludf.DUMMYFUNCTION("""COMPUTED_VALUE"""),21.0) -> 21 | B25: =IFERROR(__xludf.DUMMYFUNCTION("""COMPUTED_VALUE"""),"2526100434") -> 2526100434 | C25: =IFERROR(__xludf.DUMMYFUNCTION("""COMPUTED_VALUE"""),"0094805329") -> 0094805329 | D25: =IFERROR(__xludf.DUMMYFUNCTION("""COMPUTED_VALUE"""),"MUHAMAD NUR KHOLIS ROMDONI") -> MUHAMAD NUR KHOLIS ROMDONI | E25: =IFERROR(__xludf.DUMMYFUNCTION("""COMPUTED_VALUE"""),"X TO 4") -> X TO 4 | F25: Ganjil | G25: 77 | H25: 78 | J25: =IFERROR(AVERAGE(G25:I25),"") -> 77.5 | K25: 77 | L25: 85 | M25: 80 | O25: =IFERROR(AVERAGE(L25:N25),"") -> 82.5 | P25: 80 | Q25: 80 | R25: 80 | S25: 85 | T25: =IFERROR(AVERAGE(Q25:S25),"") -> 81.666667 | U25: 86 | V25: 75 | W25: 86 | Y25: =IFERROR(AVERAGE(V25:X25),"") -> 80.5 | Z25: 84 | AA25: 0 | AB25: 0 | AC25: 0 | AD25: =IFERROR(AVERAGE(AA25:AC25),"") -> 0 | AE25: 0 | AF25: 88 | AG25: 89 | AH25: 90 | AI25: =IFERROR(AVERAGE(AF25:AH25),"") -> 89 | AJ25: 90 | AK25: 0 | AL25: 0 | AM25: 20 | AN25: =IFERROR(AVERAGE(AK25:AM25),"") -> 6.6666667 | AO25: 0 | AP25: 72 | AQ25: =AP25 -> 72 | AR25: =AQ25 -> 72 | AS25: =IFERROR(AVERAGE(AP25:AR25),"") -> 72 | AT25: =AS25 -> 72 | AU25: 78 | AV25: 75 | AW25: 75 | AX25: =IFERROR(AVERAGE(AU25:AW25),"") -> 76 | AY25: 76 | AZ25: 80 | BA25: 80 | BC25: =IFERROR(AVERAGE(AZ25:BB25),"") -> 80 | BD25: 80 | BE25: 0 | BF25: 0 | BG25: 0 | BH25: =IFERROR(AVERAGE(BE25:BG25),"") -> 0 | BI25: 77 | BJ25: 80 | BK25: 80 | BL25: 80 | BM25: =IFERROR(AVERAGE(BJ25:BL25),"") -> 80 | BN25: 80 | BO25: 78 | BP25: 77 | BQ25: 78 | BR25: =IFERROR(AVERAGE(BO25:BQ25),"") -> 77.666667 | BS25: 77 | BW25: =IFERROR(AVERAGE(BT25:BV25),"") | CB25: =IFERROR(AVERAGE(BY25:CA25),"") | CG25: =IFERROR(AVERAGE(CD25:CF25),"")
A26: =IFERROR(__xludf.DUMMYFUNCTION("""COMPUTED_VALUE"""),22.0) -> 22 | B26: =IFERROR(__xludf.DUMMYFUNCTION("""COMPUTED_VALUE"""),"2526100435") -> 2526100435 | C26: =IFERROR(__xludf.DUMMYFUNCTION("""COMPUTED_VALUE"""),"0098562523") -> 0098562523 | D26: =IFERROR(__xludf.DUMMYFUNCTION("""COMPUTED_VALUE"""),"MUHAMAD RIDWAN") -> MUHAMAD RIDWAN | E26: =IFERROR(__xludf.DUMMYFUNCTION("""COMPUTED_VALUE"""),"X TO 4") -> X TO 4 | F26: Ganjil | G26: 79 | H26: 80 | J26: =IFERROR(AVERAGE(G26:I26),"") -> 79.5 | K26: 77 | L26: 85 | M26: 80 | O26: =IFERROR(AVERAGE(L26:N26),"") -> 82.5 | P26: 82 | Q26: 80 | R26: 87 | S26: 80 | T26: =IFERROR(AVERAGE(Q26:S26),"") -> 82.333333 | U26: 86 | V26: 80 | W26: 89 | Y26: =IFERROR(AVERAGE(V26:X26),"") -> 84.5 | Z26: 90 | AA26: 85 | AB26: 83 | AC26: 84 | AD26: =IFERROR(AVERAGE(AA26:AC26),"") -> 84 | AE26: 80 | AF26: 90 | AG26: 90 | AH26: 90 | AI26: =IFERROR(AVERAGE(AF26:AH26),"") -> 90 | AJ26: 90 | AK26: 85 | AL26: 84 | AM26: 80 | AN26: =IFERROR(AVERAGE(AK26:AM26),"") -> 83 | AO26: 86 | AP26: 72 | AQ26: =AP26 -> 72 | AR26: =AQ26 -> 72 | AS26: =IFERROR(AVERAGE(AP26:AR26),"") -> 72 | AT26: =AS26 -> 72 | AU26: 75 | AV26: 76 | AW26: 77 | AX26: =IFERROR(AVERAGE(AU26:AW26),"") -> 76 | AY26: 77 | AZ26: 80 | BA26: 80 | BC26: =IFERROR(AVERAGE(AZ26:BB26),"") -> 80 | BD26: 80 | BE26: 81 | BF26: 0 | BG26: 0 | BH26: =IFERROR(AVERAGE(BE26:BG26),"") -> 27 | BI26: 78 | BJ26: 80 | BK26: 80 | BL26: 80 | BM26: =IFERROR(AVERAGE(BJ26:BL26),"") -> 80 | BN26: 80 | BO26: 78 | BP26: 77 | BQ26: 78 | BR26: =IFERROR(AVERAGE(BO26:BQ26),"") -> 77.666667 | BS26: 78 | BW26: =IFERROR(AVERAGE(BT26:BV26),"") | CB26: =IFERROR(AVERAGE(BY26:CA26),"") | CG26: =IFERROR(AVERAGE(CD26:CF26),"")
A27: =IFERROR(__xludf.DUMMYFUNCTION("""COMPUTED_VALUE"""),23.0) -> 23 | B27: =IFERROR(__xludf.DUMMYFUNCTION("""COMPUTED_VALUE"""),"2526100436") -> 2526100436 | C27: =IFERROR(__xludf.DUMMYFUNCTION("""COMPUTED_VALUE"""),"0095384573") -> 0095384573 | D27: =IFERROR(__xludf.DUMMYFUNCTION("""COMPUTED_VALUE"""),"MUHAMAD RUDI RIVIANSYAH") -> MUHAMAD RUDI RIVIANSYAH | E27: =IFERROR(__xludf.DUMMYFUNCTION("""COMPUTED_VALUE"""),"X TO 4") -> X TO 4 | F27: Ganjil | G27: 80 | H27: 81 | J27: =IFERROR(AVERAGE(G27:I27),"") -> 80.5 | K27: 77 | L27: 85 | M27: 80 | O27: =IFERROR(AVERAGE(L27:N27),"") -> 82.5 | P27: 84 | Q27: 85 | R27: 87 | S27: 87 | T27: =IFERROR(AVERAGE(Q27:S27),"") -> 86.333333 | U27: 87 | V27: 80 | W27: 92 | Y27: =IFERROR(AVERAGE(V27:X27),"") -> 86 | Z27: 90 | AA27: 84 | AB27: 82 | AC27: 83 | AD27: =IFERROR(AVERAGE(AA27:AC27),"") -> 83 | AE27: 79 | AF27: 90 | AG27: 90 | AH27: 90 | AI27: =IFERROR(AVERAGE(AF27:AH27),"") -> 90 | AJ27: 88 | AK27: 84 | AL27: 84 | AM27: 83 | AN27: =IFERROR(AVERAGE(AK27:AM27),"") -> 83.666667 | AO27: 85 | AP27: 83 | AQ27: =AP27 -> 83 | AR27: =AQ27 -> 83 | AS27: =IFERROR(AVERAGE(AP27:AR27),"") -> 83 | AT27: =AS27 -> 83 | AU27: 76 | AV27: 78 | AW27: 80 | AX27: =IFERROR(AVERAGE(AU27:AW27),"") -> 78 | AY27: 80 | AZ27: 80 | BA27: 80 | BC27: =IFERROR(AVERAGE(AZ27:BB27),"") -> 80 | BD27: 80 | BE27: 87 | BF27: 85 | BG27: 82 | BH27: =IFERROR(AVERAGE(BE27:BG27),"") -> 84.666667 | BI27: 87 | BJ27: 85 | BK27: 80 | BL27: 80 | BM27: =IFERROR(AVERAGE(BJ27:BL27),"") -> 81.666667 | BN27: 80 | BO27: 79 | BP27: 80 | BQ27: 80 | BR27: =IFERROR(AVERAGE(BO27:BQ27),"") -> 79.666667 | BS27: 80 | BW27: =IFERROR(AVERAGE(BT27:BV27),"") | CB27: =IFERROR(AVERAGE(BY27:CA27),"") | CG27: =IFERROR(AVERAGE(CD27:CF27),"")
A28: =IFERROR(__xludf.DUMMYFUNCTION("""COMPUTED_VALUE"""),24.0) -> 24 | B28: =IFERROR(__xludf.DUMMYFUNCTION("""COMPUTED_VALUE"""),"2526100437") -> 2526100437 | C28: =IFERROR(__xludf.DUMMYFUNCTION("""COMPUTED_VALUE"""),"3098503903") -> 3098503903 | D28: =IFERROR(__xludf.DUMMYFUNCTION("""COMPUTED_VALUE"""),"MUHAMAD SALMAN") -> MUHAMAD SALMAN | E28: =IFERROR(__xludf.DUMMYFUNCTION("""COMPUTED_VALUE"""),"X TO 4") -> X TO 4 | F28: Ganjil | G28: 80 | H28: 79 | J28: =IFERROR(AVERAGE(G28:I28),"") -> 79.5 | K28: 75 | L28: 85 | M28: 80 | O28: =IFERROR(AVERAGE(L28:N28),"") -> 82.5 | P28: 79 | Q28: 78 | R28: 78 | S28: 80 | T28: =IFERROR(AVERAGE(Q28:S28),"") -> 78.666667 | U28: 85 | V28: 95 | W28: 92 | Y28: =IFERROR(AVERAGE(V28:X28),"") -> 93.5 | Z28: 84 | AA28: 75 | AB28: 73 | AC28: 74 | AD28: =IFERROR(AVERAGE(AA28:AC28),"") -> 74 | AE28: 70 | AF28: 90 | AG28: 90 | AH28: 90 | AI28: =IFERROR(AVERAGE(AF28:AH28),"") -> 90 | AJ28: 89 | AK28: 75 | AL28: 75 | AM28: 74 | AN28: =IFERROR(AVERAGE(AK28:AM28),"") -> 74.666667 | AO28: 71 | AP28: 72 | AQ28: =AP28 -> 72 | AR28: =AQ28 -> 72 | AS28: =IFERROR(AVERAGE(AP28:AR28),"") -> 72 | AT28: =AS28 -> 72 | AU28: 74 | AV28: 74 | AW28: 74 | AX28: =IFERROR(AVERAGE(AU28:AW28),"") -> 74 | AY28: 74 | AZ28: 80 | BA28: 80 | BC28: =IFERROR(AVERAGE(AZ28:BB28),"") -> 80 | BD28: 80 | BE28: 80 | BF28: 0 | BG28: 0 | BH28: =IFERROR(AVERAGE(BE28:BG28),"") -> 26.666667 | BI28: 85 | BJ28: 85 | BK28: 78 | BL28: 78 | BM28: =IFERROR(AVERAGE(BJ28:BL28),"") -> 80.333333 | BN28: 78 | BO28: 79 | BP28: 80 | BQ28: 79 | BR28: =IFERROR(AVERAGE(BO28:BQ28),"") -> 79.333333 | BS28: 80 | BW28: =IFERROR(AVERAGE(BT28:BV28),"") | CB28: =IFERROR(AVERAGE(BY28:CA28),"") | CG28: =IFERROR(AVERAGE(CD28:CF28),"")
A29: =IFERROR(__xludf.DUMMYFUNCTION("""COMPUTED_VALUE"""),25.0) -> 25 | B29: =IFERROR(__xludf.DUMMYFUNCTION("""COMPUTED_VALUE"""),"2526100438") -> 2526100438 | C29: =IFERROR(__xludf.DUMMYFUNCTION("""COMPUTED_VALUE"""),"0096750607") -> 0096750607 | D29: =IFERROR(__xludf.DUMMYFUNCTION("""COMPUTED_VALUE"""),"MUHAMAD SUTIAWAN ALI") -> MUHAMAD SUTIAWAN ALI | E29: =IFERROR(__xludf.DUMMYFUNCTION("""COMPUTED_VALUE"""),"X TO 4") -> X TO 4 | F29: Ganjil | J29: =IFERROR(AVERAGE(G29:I29),"") | O29: =IFERROR(AVERAGE(L29:N29),"") | T29: =IFERROR(AVERAGE(Q29:S29),"") | U29: 0 | V29: 75 | W29: 75 | Y29: =IFERROR(AVERAGE(V29:X29),"") -> 75 | Z29: 75 | AA29: 0 | AB29: 0 | AC29: 0 | AD29: =IFERROR(AVERAGE(AA29:AC29),"") -> 0 | AE29: 0 | AF29: 90 | AG29: 90 | AH29: 90 | AI29: =IFERROR(AVERAGE(AF29:AH29),"") -> 90 | AJ29: 89 | AK29: 0 | AL29: 0 | AM29: 0 | AN29: =IFERROR(AVERAGE(AK29:AM29),"") -> 0 | AO29: 0 | AP29: 72 | AQ29: =AP29 -> 72 | AR29: =AQ29 -> 72 | AS29: =IFERROR(AVERAGE(AP29:AR29),"") -> 72 | AT29: =AS29 -> 72 | AU29: 72 | AV29: 72 | AW29: 72 | AX29: =IFERROR(AVERAGE(AU29:AW29),"") -> 72 | AY29: 72 | AZ29: 80 | BA29: 80 | BC29: =IFERROR(AVERAGE(AZ29:BB29),"") -> 80 | BD29: 80 | BE29: 83 | BF29: 0 | BG29: 0 | BH29: =IFERROR(AVERAGE(BE29:BG29),"") -> 27.666667 | BI29: 0 | BJ29: 50 | BK29: 50 | BL29: 50 | BM29: =IFERROR(AVERAGE(BJ29:BL29),"") -> 50 | BN29: 50 | BO29: 45 | BP29: 50 | BQ29: 45 | BR29: =IFERROR(AVERAGE(BO29:BQ29),"") -> 46.666667 | BS29: 0 | BW29: =IFERROR(AVERAGE(BT29:BV29),"") | CB29: =IFERROR(AVERAGE(BY29:CA29),"") | CG29: =IFERROR(AVERAGE(CD29:CF29),"")
A30: =IFERROR(__xludf.DUMMYFUNCTION("""COMPUTED_VALUE"""),26.0) -> 26 | B30: =IFERROR(__xludf.DUMMYFUNCTION("""COMPUTED_VALUE"""),"2526100439") -> 2526100439 | C30: =IFERROR(__xludf.DUMMYFUNCTION("""COMPUTED_VALUE"""),"0094990767") -> 0094990767 | D30: =IFERROR(__xludf.DUMMYFUNCTION("""COMPUTED_VALUE"""),"MUHAMMAD FAHRI MAULANA") -> MUHAMMAD FAHRI MAULANA | E30: =IFERROR(__xludf.DUMMYFUNCTION("""COMPUTED_VALUE"""),"X TO 4") -> X TO 4 | F30: Ganjil | G30: 78 | H30: 78 | J30: =IFERROR(AVERAGE(G30:I30),"") -> 78 | K30: 75 | L30: 85 | M30: 80 | O30: =IFERROR(AVERAGE(L30:N30),"") -> 82.5 | P30: 81 | Q30: 76 | R30: 78 | S30: 80 | T30: =IFERROR(AVERAGE(Q30:S30),"") -> 78 | U30: 80 | V30: 80 | W30: 96 | Y30: =IFERROR(AVERAGE(V30:X30),"") -> 88 | Z30: 80 | AA30: 75 | AB30: 73 | AC30: 74 | AD30: =IFERROR(AVERAGE(AA30:AC30),"") -> 74 | AE30: 70 | AF30: 90 | AG30: 89 | AH30: 90 | AI30: =IFERROR(AVERAGE(AF30:AH30),"") -> 89.666667 | AJ30: 88 | AK30: 75 | AL30: 74 | AM30: 74 | AN30: =IFERROR(AVERAGE(AK30:AM30),"") -> 74.333333 | AO30: 70 | AP30: 72 | AQ30: =AP30 -> 72 | AR30: =AQ30 -> 72 | AS30: =IFERROR(AVERAGE(AP30:AR30),"") -> 72 | AT30: =AS30 -> 72 | AU30: 72 | AV30: 72 | AW30: 72 | AX30: =IFERROR(AVERAGE(AU30:AW30),"") -> 72 | AY30: 72 | AZ30: 80 | BA30: 80 | BC30: =IFERROR(AVERAGE(AZ30:BB30),"") -> 80 | BD30: 80 | BE30: 83 | BF30: 0 | BG30: 0 | BH30: =IFERROR(AVERAGE(BE30:BG30),"") -> 27.666667 | BI30: 77 | BJ30: 75 | BK30: 80 | BL30: 80 | BM30: =IFERROR(AVERAGE(BJ30:BL30),"") -> 78.333333 | BN30: 80 | BO30: 78 | BP30: 77 | BQ30: 78 | BR30: =IFERROR(AVERAGE(BO30:BQ30),"") -> 77.666667 | BS30: 77 | BW30: =IFERROR(AVERAGE(BT30:BV30),"") | CB30: =IFERROR(AVERAGE(BY30:CA30),"") | CG30: =IFERROR(AVERAGE(CD30:CF30),"")
A31: =IFERROR(__xludf.DUMMYFUNCTION("""COMPUTED_VALUE"""),27.0) -> 27 | B31: =IFERROR(__xludf.DUMMYFUNCTION("""COMPUTED_VALUE"""),"2526100440") -> 2526100440 | C31: =IFERROR(__xludf.DUMMYFUNCTION("""COMPUTED_VALUE"""),"0105005356") -> 0105005356 | D31: =IFERROR(__xludf.DUMMYFUNCTION("""COMPUTED_VALUE"""),"MUHAMMAD GALANG GUNAWAN") -> MUHAMMAD GALANG GUNAWAN | E31: =IFERROR(__xludf.DUMMYFUNCTION("""COMPUTED_VALUE"""),"X TO 4") -> X TO 4 | F31: Ganjil | G31: 75 | H31: 75 | J31: =IFERROR(AVERAGE(G31:I31),"") -> 75 | K31: 75 | L31: 75 | M31: 75 | O31: =IFERROR(AVERAGE(L31:N31),"") -> 75 | P31: 75 | Q31: 76 | R31: 76 | S31: 75 | T31: =IFERROR(AVERAGE(Q31:S31),"") -> 75.666667 | U31: 75 | V31: 75 | W31: 75 | Y31: =IFERROR(AVERAGE(V31:X31),"") -> 75 | Z31: 75 | AA31: 75 | AB31: 75 | AC31: 75 | AD31: =IFERROR(AVERAGE(AA31:AC31),"") -> 75 | AE31: 75 | AF31: 90 | AG31: 90 | AH31: 88 | AI31: =IFERROR(AVERAGE(AF31:AH31),"") -> 89.333333 | AJ31: 89 | AK31: 75 | AL31: 75 | AM31: 75 | AN31: =IFERROR(AVERAGE(AK31:AM31),"") -> 75 | AO31: 75 | AP31: 75 | AQ31: 75 | AR31: =AQ31 -> 75 | AS31: =IFERROR(AVERAGE(AP31:AR31),"") -> 75 | AT31: =AS31 -> 75 | AU31: 75 | AV31: 75 | AW31: 75 | AX31: =IFERROR(AVERAGE(AU31:AW31),"") -> 75 | AY31: 75 | AZ31: 80 | BA31: 80 | BC31: =IFERROR(AVERAGE(AZ31:BB31),"") -> 80 | BD31: 80 | BE31: 75 | BF31: 75 | BG31: 75 | BH31: =IFERROR(AVERAGE(BE31:BG31),"") -> 75 | BI31: 75 | BJ31: 75 | BK31: 75 | BL31: 75 | BM31: =IFERROR(AVERAGE(BJ31:BL31),"") -> 75 | BN31: 75 | BO31: 75 | BP31: 75 | BQ31: 75 | BR31: =IFERROR(AVERAGE(BO31:BQ31),"") -> 75 | BS31: 75 | BW31: =IFERROR(AVERAGE(BT31:BV31),"") | CB31: =IFERROR(AVERAGE(BY31:CA31),"") | CG31: =IFERROR(AVERAGE(CD31:CF31),"")
A32: =IFERROR(__xludf.DUMMYFUNCTION("""COMPUTED_VALUE"""),28.0) -> 28 | B32: =IFERROR(__xludf.DUMMYFUNCTION("""COMPUTED_VALUE"""),"2526100441") -> 2526100441 | C32: =IFERROR(__xludf.DUMMYFUNCTION("""COMPUTED_VALUE"""),"0089904752") -> 0089904752 | D32: =IFERROR(__xludf.DUMMYFUNCTION("""COMPUTED_VALUE"""),"MUHAMMAD GOZALI") -> MUHAMMAD GOZALI | E32: =IFERROR(__xludf.DUMMYFUNCTION("""COMPUTED_VALUE"""),"X TO 4") -> X TO 4 | F32: Ganjil | G32: 80 | H32: 80 | J32: =IFERROR(AVERAGE(G32:I32),"") -> 80 | K32: 75 | L32: 85 | M32: 80 | O32: =IFERROR(AVERAGE(L32:N32),"") -> 82.5 | P32: 83 | Q32: 78 | R32: 87 | S32: 85 | T32: =IFERROR(AVERAGE(Q32:S32),"") -> 83.333333 | U32: 85 | V32: 97 | W32: 87 | Y32: =IFERROR(AVERAGE(V32:X32),"") -> 92 | Z32: 90 | AA32: 86 | AB32: 84 | AC32: 85 | AD32: =IFERROR(AVERAGE(AA32:AC32),"") -> 85 | AE32: 81 | AF32: 90 | AG32: 89 | AH32: 89 | AI32: =IFERROR(AVERAGE(AF32:AH32),"") -> 89.333333 | AJ32: 90 | AK32: 86 | AL32: 86 | AM32: 84 | AN32: =IFERROR(AVERAGE(AK32:AM32),"") -> 85.333333 | AO32: 86 | AP32: 75 | AQ32: =AP32 -> 75 | AR32: =AQ32 -> 75 | AS32: =IFERROR(AVERAGE(AP32:AR32),"") -> 75 | AT32: =AS32 -> 75 | AU32: 76 | AV32: 78 | AW32: 80 | AX32: =IFERROR(AVERAGE(AU32:AW32),"") -> 78 | AY32: 76 | AZ32: 80 | BA32: 80 | BC32: =IFERROR(AVERAGE(AZ32:BB32),"") -> 80 | BD32: 80 | BE32: 88 | BF32: 80 | BG32: 80 | BH32: =IFERROR(AVERAGE(BE32:BG32),"") -> 82.666667 | BI32: 83 | BJ32: 83 | BK32: 80 | BL32: 80 | BM32: =IFERROR(AVERAGE(BJ32:BL32),"") -> 81 | BN32: 80 | BO32: 78 | BP32: 78 | BQ32: 78 | BR32: =IFERROR(AVERAGE(BO32:BQ32),"") -> 78 | BS32: 77 | BW32: =IFERROR(AVERAGE(BT32:BV32),"") | CB32: =IFERROR(AVERAGE(BY32:CA32),"") | CG32: =IFERROR(AVERAGE(CD32:CF32),"")
A33: =IFERROR(__xludf.DUMMYFUNCTION("""COMPUTED_VALUE"""),29.0) -> 29 | B33: =IFERROR(__xludf.DUMMYFUNCTION("""COMPUTED_VALUE"""),"2526100442") -> 2526100442 | C33: =IFERROR(__xludf.DUMMYFUNCTION("""COMPUTED_VALUE"""),"0093764470") -> 0093764470 | D33: =IFERROR(__xludf.DUMMYFUNCTION("""COMPUTED_VALUE"""),"MUHAMMAD HADAD AT'TOILLAH") -> MUHAMMAD HADAD AT'TOILLAH | E33: =IFERROR(__xludf.DUMMYFUNCTION("""COMPUTED_VALUE"""),"X TO 4") -> X TO 4 | F33: Ganjil | G33: 78 | H33: 79 | J33: =IFERROR(AVERAGE(G33:I33),"") -> 78.5 | L33: 85 | M33: 80 | O33: =IFERROR(AVERAGE(L33:N33),"") -> 82.5 | P33: 80 | Q33: 78 | R33: 80 | S33: 85 | T33: =IFERROR(AVERAGE(Q33:S33),"") -> 81 | U33: 80 | V33: 75 | W33: 90 | Y33: =IFERROR(AVERAGE(V33:X33),"") -> 82.5 | Z33: 80 | AA33: 83 | AB33: 81 | AC33: 82 | AD33: =IFERROR(AVERAGE(AA33:AC33),"") -> 82 | AE33: 78 | AF33: 90 | AG33: 90 | AH33: 90 | AI33: =IFERROR(AVERAGE(AF33:AH33),"") -> 90 | AJ33: 90 | AK33: 83 | AL33: 82 | AM33: 81 | AN33: =IFERROR(AVERAGE(AK33:AM33),"") -> 82 | AO33: 78 | AP33: 72 | AQ33: =AP33 -> 72 | AR33: =AQ33 -> 72 | AS33: =IFERROR(AVERAGE(AP33:AR33),"") -> 72 | AT33: =AS33 -> 72 | AU33: 74 | AV33: 76 | AW33: 78 | AX33: =IFERROR(AVERAGE(AU33:AW33),"") -> 76 | AY33: 74 | AZ33: 80 | BA33: 80 | BC33: =IFERROR(AVERAGE(AZ33:BB33),"") -> 80 | BD33: 80 | BE33: 87 | BF33: 78 | BG33: 80 | BH33: =IFERROR(AVERAGE(BE33:BG33),"") -> 81.666667 | BI33: 83 | BJ33: 85 | BK33: 80 | BL33: 80 | BM33: =IFERROR(AVERAGE(BJ33:BL33),"") -> 81.666667 | BN33: 80 | BO33: 77 | BP33: 78 | BQ33: 78 | BR33: =IFERROR(AVERAGE(BO33:BQ33),"") -> 77.666667 | BS33: 77 | BW33: =IFERROR(AVERAGE(BT33:BV33),"") | CB33: =IFERROR(AVERAGE(BY33:CA33),"") | CG33: =IFERROR(AVERAGE(CD33:CF33),"")
A34: =IFERROR(__xludf.DUMMYFUNCTION("""COMPUTED_VALUE"""),30.0) -> 30 | B34: =IFERROR(__xludf.DUMMYFUNCTION("""COMPUTED_VALUE"""),"2526100443") -> 2526100443 | C34: =IFERROR(__xludf.DUMMYFUNCTION("""COMPUTED_VALUE"""),"0092995954") -> 0092995954 | D34: =IFERROR(__xludf.DUMMYFUNCTION("""COMPUTED_VALUE"""),"MUHAMMAD ILHAM") -> MUHAMMAD ILHAM | E34: =IFERROR(__xludf.DUMMYFUNCTION("""COMPUTED_VALUE"""),"X TO 4") -> X TO 4 | F34: Ganjil | G34: 80 | H34: 81 | J34: =IFERROR(AVERAGE(G34:I34),"") -> 80.5 | K34: 80 | L34: 85 | M34: 80 | O34: =IFERROR(AVERAGE(L34:N34),"") -> 82.5 | P34: 82 | Q34: 78 | R34: 80 | S34: 80 | T34: =IFERROR(AVERAGE(Q34:S34),"") -> 79.333333 | U34: 80 | V34: 80 | W34: 91 | Y34: =IFERROR(AVERAGE(V34:X34),"") -> 85.5 | Z34: 80 | AA34: 70 | AB34: 68 | AC34: 69 | AD34: =IFERROR(AVERAGE(AA34:AC34),"") -> 69 | AE34: 65 | AF34: 90 | AG34: 90 | AH34: 89 | AI34: =IFERROR(AVERAGE(AF34:AH34),"") -> 89.666667 | AJ34: 90 | AK34: 70 | AL34: 0 | AM34: 0 | AN34: =IFERROR(AVERAGE(AK34:AM34),"") -> 23.333333 | AO34: 20 | AP34: 72 | AQ34: =AP34 -> 72 | AR34: =AQ34 -> 72 | AS34: =IFERROR(AVERAGE(AP34:AR34),"") -> 72 | AT34: =AS34 -> 72 | AU34: 72 | AV34: 72 | AW34: 72 | AX34: =IFERROR(AVERAGE(AU34:AW34),"") -> 72 | AY34: 72 | AZ34: 80 | BA34: 80 | BC34: =IFERROR(AVERAGE(AZ34:BB34),"") -> 80 | BD34: 80 | BE34: 85 | BF34: 0 | BG34: 0 | BH34: =IFERROR(AVERAGE(BE34:BG34),"") -> 28.333333 | BI34: 80 | BJ34: 83 | BK34: 80 | BL34: 80 | BM34: =IFERROR(AVERAGE(BJ34:BL34),"") -> 81 | BN34: 80 | BO34: 79 | BP34: 80 | BQ34: 79 | BR34: =IFERROR(AVERAGE(BO34:BQ34),"") -> 79.333333 | BS34: 79 | BW34: =IFERROR(AVERAGE(BT34:BV34),"") | CB34: =IFERROR(AVERAGE(BY34:CA34),"") | CG34: =IFERROR(AVERAGE(CD34:CF34),"")
